Workbook

Sheet Navodila
B1: NAVODILA ZA UPORABO
B3: 1. List Nastavitve: vpišite ime in priimek, delovno mesto, enote, leto in veljavno kilometrino (€/km).
B4: 2. List Relacije: vpišite relacije in kilometre v ENO smer. Seznam lahko poljubno dopolnjujete (do 100 relacij).
B5: 3. Mesečni listi (Januar ... December): stolpec DATUM je že izpolnjen z delovnimi dnevi meseca
B6: (brez sobot, nedelj in praznikov s lista Nastavitve). Za dan s službeno potjo vpišite
B7: DOGODEK / NAMEN POTI → DOGODEK / NAMEN POTI → izberite RELACIJO s seznama → izberite POT (tja in nazaj / ena smer).
B8: KILOMETRI in VREDNOST se izračunata samodejno (prazna POT pomeni tja in nazaj).
B9: Pot na dela prost dan ali drugo pot v istem dnevu vpišite v prazne vrstice pod zadnjim delovnim dnem.
B10: 4. List Letni pregled samodejno povzame število poti, kilometre in znesek po mesecih.
B11: 5. Mesečni list je pripravljen za tisk na A4 ležeče (podpisni list).
B13: Rumene celice = vnos podatkov. Ostale celice vsebujejo formule - ne prepisujte jih.
B15: PRIMER VNOSA:
B16: 1.9.2026 | Popoldanska delavnica | Šmartno pri Cerkljah - Križe | tja in nazaj → 34,9 km | 15,01 € (pri 0,43 €/km)

Sheet Nastavitve
B1: NASTAVITVE
B2: Rumene celice izpolnite. Podatki se samodejno prenesejo na vse mesečne liste.
E3: KILOMETRINA
B4: Ime in priimek | C4: Ime Priimek | E4: velja od | F4: € / km
B5: Delovno mesto / enota | C5: Enota | E5: =DATE(Leto,1,1) -> 46023 | F5: 0.43
B6: Enote (izpis pod mesecem) | C6: PALČEK, KRIŽE, DETELJICA, LOM, KOVOR
B7: Leto | C7: 2026
E11: Ob spremembi vpišite nov datum in znesek v naslednjo vrstico (datumi naraščajoče).
B15: DELA PROSTI DNEVI (PRAZNIKI)
B16: praznik | C16: datum
B17: Novo leto | C17: =DATE(Leto,1,1) -> 46023
B18: Novo leto | C18: =DATE(Leto,1,2) -> 46024
B19: Prešernov dan | C19: =DATE(Leto,2,8) -> 46061
B20: Velikonočni ponedeljek | C20: =(FLOOR(DATE(Leto,5,DAY(MINUTE(Leto/38)/2+56)),7)-34)+1 -> 46118
B21: Dan upora proti okupatorju | C21: =DATE(Leto,4,27) -> 46139
B22: Praznik dela | C22: =DATE(Leto,5,1) -> 46143
B23: Praznik dela | C23: =DATE(Leto,5,2) -> 46144
B24: Dan državnosti | C24: =DATE(Leto,6,25) -> 46198
B25: Marijino vnebovzetje | C25: =DATE(Leto,8,15) -> 46249
B26: Dan reformacije | C26: =DATE(Leto,10,31) -> 46326
B27: Dan spomina na mrtve | C27: =DATE(Leto,11,1) -> 46327
B28: Božič | C28: =DATE(Leto,12,25) -> 46381
B29: Dan samostojnosti in enotnosti | C29: =DATE(Leto,12,26) -> 46382
B37: Prazniki se samodejno izračunajo za izbrano leto (velika noč po formuli). V rumene vrstice lahko dodate druge dela proste dneve.

Sheet Relacije
B1: KILOMETRI MED ENOTAMI / RELACIJE
B2: Vpišite relacijo in kilometre v eno smer (rumeno). Obe smeri se izračunata samodejno.
B4: RELACIJA | C4: KILOMETRI ENA SMER | D4: KILOMETRI OBE SMERI
B5: Šmartno pri Cerkljah - Križe | C5: 17.45 | D5: =IF(C5="","",C5*2) -> 34.9
B6: Šmartno pri Cerkljah - Palček | C6: 14.8 | D6: =IF(C6="","",C6*2) -> 29.6
B7: Šmartno pri Cerkljah - Lom | C7: 18 | D7: =IF(C7="","",C7*2) -> 36
B8: Šmartno pri Cerkljah - Deteljica | C8: 16.5 | D8: =IF(C8="","",C8*2) -> 33
B9: Križe - Muzej | C9: 3.5 | D9: =IF(C9="","",C9*2) -> 7
B10: Križe - Kovor | C10: 1.6 | D10: =IF(C10="","",C10*2) -> 3.2
B11: Palček - Občina | C11: 1.1 | D11: =IF(C11="","",C11*2) -> 2.2
B12: Palček - Deteljica | C12: 1.2 | D12: =IF(C12="","",C12*2) -> 2.4
B13: Palček - Kovor | C13: 2.8 | D13: =IF(C13="","",C13*2) -> 5.6
B14: Palček - Križe | C14: 2.7 | D14: =IF(C14="","",C14*2) -> 5.4
B15: Palček - OŠ Tržič | C15: 1.5 | D15: =IF(C15="","",C15*2) -> 3
B16: Palček - Lom | C16: 3.3 | D16: =IF(C16="","",C16*2) -> 6.6
... B21: Deteljica - Križe | C21: 2.7 | D21: =IF(C21="","",C21*2) -> 5.4
D22: =IF(C22="","",C22*2)
D23: =IF(C23="","",C23*2)
D24: =IF(C24="","",C24*2)
D25: =IF(C25="","",C25*2)
D26: =IF(C26="","",C26*2)
D27: =IF(C27="","",C27*2)
D28: =IF(C28="","",C28*2)
D29: =IF(C29="","",C29*2)
D30: =IF(C30="","",C30*2)
D31: =IF(C31="","",C31*2)
D32: =IF(C32="","",C32*2)
D33: =IF(C33="","",C33*2)
... D104: =IF(C104="","",C104*2)

Sheet Letni pregled
B1: LETNI PREGLED KILOMETRINE
B2: ="Leto "&Leto&" - "&Ime -> Leto 2026 - Ime Priimek
B4: MESEC | C4: ŠT. POTI | D4: KILOMETRI | E4: VREDNOST | F4: DELOVNI DNEVI
B5: Januar | C5: =COUNT(Januar!F10:F40) -> 0 | D5: =Januar!F41 -> 0 | E5: =Januar!G41 -> 0 | F5: =Januar!J4 -> 20
B6: Februar | C6: =COUNT(Februar!F10:F40) -> 0 | D6: =Februar!F41 -> 0 | E6: =Februar!G41 -> 0 | F6: =Februar!J4 -> 20
B7: Marec | C7: =COUNT(Marec!F10:F40) -> 0 | D7: =Marec!F41 -> 0 | E7: =Marec!G41 -> 0 | F7: =Marec!J4 -> 22
B8: April | C8: =COUNT(April!F10:F40) -> 0 | D8: =April!F41 -> 0 | E8: =April!G41 -> 0 | F8: =April!J4 -> 20
B9: Maj | C9: =COUNT(Maj!F10:F40) -> 0 | D9: =Maj!F41 -> 0 | E9: =Maj!G41 -> 0 | F9: =Maj!J4 -> 20
B10: Junij | C10: =COUNT(Junij!F10:F40) -> 0 | D10: =Junij!F41 -> 0 | E10: =Junij!G41 -> 0 | F10: =Junij!J4 -> 21
B11: Julij | C11: =COUNT(Julij!F10:F40) -> 0 | D11: =Julij!F41 -> 0 | E11: =Julij!G41 -> 0 | F11: =Julij!J4 -> 23
B12: Avgust | C12: =COUNT(Avgust!F10:F40) -> 0 | D12: =Avgust!F41 -> 0 | E12: =Avgust!G41 -> 0 | F12: =Avgust!J4 -> 21
B13: September | C13: =COUNT(September!F10:F40) -> 0 | D13: =September!F41 -> 0 | E13: =September!G41 -> 0 | F13: =September!J4 -> 22
B14: Oktober | C14: =COUNT(Oktober!F10:F40) -> 0 | D14: =Oktober!F41 -> 0 | E14: =Oktober!G41 -> 0 | F14: =Oktober!J4 -> 22
B15: November | C15: =COUNT(November!F10:F40) -> 0 | D15: =November!F41 -> 0 | E15: =November!G41 -> 0 | F15: =November!J4 -> 21
B16: December | C16: =COUNT(December!F10:F40) -> 0 | D16: =December!F41 -> 0 | E16: =December!G41 -> 0 | F16: =December!J4 -> 22
B17: SKUPAJ | C17: =SUM(C5:C16) -> 0 | D17: =SUM(D5:D16) -> 0 | E17: =SUM(E5:E16) -> 0 | F17: =SUM(F5:F16) -> 254

Sheet Januar
B1: PODPISNI LIST - KILOMETRINA SLUŽBENIH POTI
I2: kilometrina
B3: =Ime -> Ime Priimek | I3: € / km | J3: =INDEX(KmCene,MATCH(DATE(Leto,1,1),KmDatumi,1)) -> 0.43
B4: =DelovnoMesto -> Enota | I4: delovni dnevi | J4: =NETWORKDAYS(DATE(Leto,1,1),EOMONTH(DATE(Leto,1,1),0),Prazniki) -> 20
B5: =DATE(Leto,1,1) -> 46023
B6: =Enote -> PALČEK, KRIŽE, DETELJICA, LOM, KOVOR
B9: DATUM | C9: DOGODEK / NAMEN POTI | D9: RELACIJA* | E9: POT | F9: KILOMETRI | G9: VREDNOST**
B10: =IF(WORKDAY(DATE(Leto,1,1)-1,1,Prazniki)>EOMONTH(DATE(Leto,1,1),0),"",WORKDAY(DATE(Leto,1,1)-1,1,Prazniki)) -> 46027 | F10: =IF(D10="","",IFERROR(INDEX(RelKm,MATCH(D10,RelNazivi,0))*IF(E10="ena smer",1,2),"")) | G10: =IF(F10="","",ROUND(F10*$J$3,2))
B11: =IF(WORKDAY(DATE(Leto,1,1)-1,2,Prazniki)>EOMONTH(DATE(Leto,1,1),0),"",WORKDAY(DATE(Leto,1,1)-1,2,Prazniki)) -> 46028 | F11: =IF(D11="","",IFERROR(INDEX(RelKm,MATCH(D11,RelNazivi,0))*IF(E11="ena smer",1,2),"")) | G11: =IF(F11="","",ROUND(F11*$J$3,2))
B12: =IF(WORKDAY(DATE(Leto,1,1)-1,3,Prazniki)>EOMONTH(DATE(Leto,1,1),0),"",WORKDAY(DATE(Leto,1,1)-1,3,Prazniki)) -> 46029 | F12: =IF(D12="","",IFERROR(INDEX(RelKm,MATCH(D12,RelNazivi,0))*IF(E12="ena smer",1,2),"")) | G12: =IF(F12="","",ROUND(F12*$J$3,2))
B13: =IF(WORKDAY(DATE(Leto,1,1)-1,4,Prazniki)>EOMONTH(DATE(Leto,1,1),0),"",WORKDAY(DATE(Leto,1,1)-1,4,Prazniki)) -> 46030 | F13: =IF(D13="","",IFERROR(INDEX(RelKm,MATCH(D13,RelNazivi,0))*IF(E13="ena smer",1,2),"")) | G13: =IF(F13="","",ROUND(F13*$J$3,2))
B14: =IF(WORKDAY(DATE(Leto,1,1)-1,5,Prazniki)>EOMONTH(DATE(Leto,1,1),0),"",WORKDAY(DATE(Leto,1,1)-1,5,Prazniki)) -> 46031 | F14: =IF(D14="","",IFERROR(INDEX(RelKm,MATCH(D14,RelNazivi,0))*IF(E14="ena smer",1,2),"")) | G14: =IF(F14="","",ROUND(F14*$J$3,2))
B15: =IF(WORKDAY(DATE(Leto,1,1)-1,6,Prazniki)>EOMONTH(DATE(Leto,1,1),0),"",WORKDAY(DATE(Leto,1,1)-1,6,Prazniki)) -> 46034 | F15: =IF(D15="","",IFERROR(INDEX(RelKm,MATCH(D15,RelNazivi,0))*IF(E15="ena smer",1,2),"")) | G15: =IF(F15="","",ROUND(F15*$J$3,2))
B16: =IF(WORKDAY(DATE(Leto,1,1)-1,7,Prazniki)>EOMONTH(DATE(Leto,1,1),0),"",WORKDAY(DATE(Leto,1,1)-1,7,Prazniki)) -> 46035 | F16: =IF(D16="","",IFERROR(INDEX(RelKm,MATCH(D16,RelNazivi,0))*IF(E16="ena smer",1,2),"")) | G16: =IF(F16="","",ROUND(F16*$J$3,2))
B17: =IF(WORKDAY(DATE(Leto,1,1)-1,8,Prazniki)>EOMONTH(DATE(Leto,1,1),0),"",WORKDAY(DATE(Leto,1,1)-1,8,Prazniki)) -> 46036 | F17: =IF(D17="","",IFERROR(INDEX(RelKm,MATCH(D17,RelNazivi,0))*IF(E17="ena smer",1,2),"")) | G17: =IF(F17="","",ROUND(F17*$J$3,2))
B18: =IF(WORKDAY(DATE(Leto,1,1)-1,9,Prazniki)>EOMONTH(DATE(Leto,1,1),0),"",WORKDAY(DATE(Leto,1,1)-1,9,Prazniki)) -> 46037 | F18: =IF(D18="","",IFERROR(INDEX(RelKm,MATCH(D18,RelNazivi,0))*IF(E18="ena smer",1,2),"")) | G18: =IF(F18="","",ROUND(F18*$J$3,2))
B19: =IF(WORKDAY(DATE(Leto,1,1)-1,10,Prazniki)>EOMONTH(DATE(Leto,1,1),0),"",WORKDAY(DATE(Leto,1,1)-1,10,Prazniki)) -> 46038 | F19: =IF(D19="","",IFERROR(INDEX(RelKm,MATCH(D19,RelNazivi,0))*IF(E19="ena smer",1,2),"")) | G19: =IF(F19="","",ROUND(F19*$J$3,2))
B20: =IF(WORKDAY(DATE(Leto,1,1)-1,11,Prazniki)>EOMONTH(DATE(Leto,1,1),0),"",WORKDAY(DATE(Leto,1,1)-1,11,Prazniki)) -> 46041 | F20: =IF(D20="","",IFERROR(INDEX(RelKm,MATCH(D20,RelNazivi,0))*IF(E20="ena smer",1,2),"")) | G20: =IF(F20="","",ROUND(F20*$J$3,2))
B21: =IF(WORKDAY(DATE(Leto,1,1)-1,12,Prazniki)>EOMONTH(DATE(Leto,1,1),0),"",WORKDAY(DATE(Leto,1,1)-1,12,Prazniki)) -> 46042 | F21: =IF(D21="","",IFERROR(INDEX(RelKm,MATCH(D21,RelNazivi,0))*IF(E21="ena smer",1,2),"")) | G21: =IF(F21="","",ROUND(F21*$J$3,2))
B22: =IF(WORKDAY(DATE(Leto,1,1)-1,13,Prazniki)>EOMONTH(DATE(Leto,1,1),0),"",WORKDAY(DATE(Leto,1,1)-1,13,Prazniki)) -> 46043 | F22: =IF(D22="","",IFERROR(INDEX(RelKm,MATCH(D22,RelNazivi,0))*IF(E22="ena smer",1,2),"")) | G22: =IF(F22="","",ROUND(F22*$J$3,2))
B23: =IF(WORKDAY(DATE(Leto,1,1)-1,14,Prazniki)>EOMONTH(DATE(Leto,1,1),0),"",WORKDAY(DATE(Leto,1,1)-1,14,Prazniki)) -> 46044 | F23: =IF(D23="","",IFERROR(INDEX(RelKm,MATCH(D23,RelNazivi,0))*IF(E23="ena smer",1,2),"")) | G23: =IF(F23="","",ROUND(F23*$J$3,2))
B24: =IF(WORKDAY(DATE(Leto,1,1)-1,15,Prazniki)>EOMONTH(DATE(Leto,1,1),0),"",WORKDAY(DATE(Leto,1,1)-1,15,Prazniki)) -> 46045 | F24: =IF(D24="","",IFERROR(INDEX(RelKm,MATCH(D24,RelNazivi,0))*IF(E24="ena smer",1,2),"")) | G24: =IF(F24="","",ROUND(F24*$J$3,2))
B25: =IF(WORKDAY(DATE(Leto,1,1)-1,16,Prazniki)>EOMONTH(DATE(Leto,1,1),0),"",WORKDAY(DATE(Leto,1,1)-1,16,Prazniki)) -> 46048 | F25: =IF(D25="","",IFERROR(INDEX(RelKm,MATCH(D25,RelNazivi,0))*IF(E25="ena smer",1,2),"")) | G25: =IF(F25="","",ROUND(F25*$J$3,2))
B26: =IF(WORKDAY(DATE(Leto,1,1)-1,17,Prazniki)>EOMONTH(DATE(Leto,1,1),0),"",WORKDAY(DATE(Leto,1,1)-1,17,Prazniki)) -> 46049 | F26: =IF(D26="","",IFERROR(INDEX(RelKm,MATCH(D26,RelNazivi,0))*IF(E26="ena smer",1,2),"")) | G26: =IF(F26="","",ROUND(F26*$J$3,2))
B27: =IF(WORKDAY(DATE(Leto,1,1)-1,18,Prazniki)>EOMONTH(DATE(Leto,1,1),0),"",WORKDAY(DATE(Leto,1,1)-1,18,Prazniki)) -> 46050 | F27: =IF(D27="","",IFERROR(INDEX(RelKm,MATCH(D27,RelNazivi,0))*IF(E27="ena smer",1,2),"")) | G27: =IF(F27="","",ROUND(F27*$J$3,2))
B28: =IF(WORKDAY(DATE(Leto,1,1)-1,19,Prazniki)>EOMONTH(DATE(Leto,1,1),0),"",WORKDAY(DATE(Leto,1,1)-1,19,Prazniki)) -> 46051 | F28: =IF(D28="","",IFERROR(INDEX(RelKm,MATCH(D28,RelNazivi,0))*IF(E28="ena smer",1,2),"")) | G28: =IF(F28="","",ROUND(F28*$J$3,2))
B29: =IF(WORKDAY(DATE(Leto,1,1)-1,20,Prazniki)>EOMONTH(DATE(Leto,1,1),0),"",WORKDAY(DATE(Leto,1,1)-1,20,Prazniki)) -> 46052 | F29: =IF(D29="","",IFERROR(INDEX(RelKm,MATCH(D29,RelNazivi,0))*IF(E29="ena smer",1,2),"")) | G29: =IF(F29="","",ROUND(F29*$J$3,2))
B30: =IF(WORKDAY(DATE(Leto,1,1)-1,21,Prazniki)>EOMONTH(DATE(Leto,1,1),0),"",WORKDAY(DATE(Leto,1,1)-1,21,Prazniki)) | F30: =IF(D30="","",IFERROR(INDEX(RelKm,MATCH(D30,RelNazivi,0))*IF(E30="ena smer",1,2),"")) | G30: =IF(F30="","",ROUND(F30*$J$3,2))
B31: =IF(WORKDAY(DATE(Leto,1,1)-1,22,Prazniki)>EOMONTH(DATE(Leto,1,1),0),"",WORKDAY(DATE(Leto,1,1)-1,22,Prazniki)) | F31: =IF(D31="","",IFERROR(INDEX(RelKm,MATCH(D31,RelNazivi,0))*IF(E31="ena smer",1,2),"")) | G31: =IF(F31="","",ROUND(F31*$J$3,2))
B32: =IF(WORKDAY(DATE(Leto,1,1)-1,23,Prazniki)>EOMONTH(DATE(Leto,1,1),0),"",WORKDAY(DATE(Leto,1,1)-1,23,Prazniki)) | F32: =IF(D32="","",IFERROR(INDEX(RelKm,MATCH(D32,RelNazivi,0))*IF(E32="ena smer",1,2),"")) | G32: =IF(F32="","",ROUND(F32*$J$3,2))
B33: =IF(WORKDAY(DATE(Leto,1,1)-1,24,Prazniki)>EOMONTH(DATE(Leto,1,1),0),"",WORKDAY(DATE(Leto,1,1)-1,24,Prazniki)) | F33: =IF(D33="","",IFERROR(INDEX(RelKm,MATCH(D33,RelNazivi,0))*IF(E33="ena smer",1,2),"")) | G33: =IF(F33="","",ROUND(F33*$J$3,2))
B34: =IF(WORKDAY(DATE(Leto,1,1)-1,25,Prazniki)>EOMONTH(DATE(Leto,1,1),0),"",WORKDAY(DATE(Leto,1,1)-1,25,Prazniki)) | F34: =IF(D34="","",IFERROR(INDEX(RelKm,MATCH(D34,RelNazivi,0))*IF(E34="ena smer",1,2),"")) | G34: =IF(F34="","",ROUND(F34*$J$3,2))
B35: =IF(WORKDAY(DATE(Leto,1,1)-1,26,Prazniki)>EOMONTH(DATE(Leto,1,1),0),"",WORKDAY(DATE(Leto,1,1)-1,26,Prazniki)) | F35: =IF(D35="","",IFERROR(INDEX(RelKm,MATCH(D35,RelNazivi,0))*IF(E35="ena smer",1,2),"")) | G35: =IF(F35="","",ROUND(F35*$J$3,2))
B36: =IF(WORKDAY(DATE(Leto,1,1)-1,27,Prazniki)>EOMONTH(DATE(Leto,1,1),0),"",WORKDAY(DATE(Leto,1,1)-1,27,Prazniki)) | F36: =IF(D36="","",IFERROR(INDEX(RelKm,MATCH(D36,RelNazivi,0))*IF(E36="ena smer",1,2),"")) | G36: =IF(F36="","",ROUND(F36*$J$3,2))
B37: =IF(WORKDAY(DATE(Leto,1,1)-1,28,Prazniki)>EOMONTH(DATE(Leto,1,1),0),"",WORKDAY(DATE(Leto,1,1)-1,28,Prazniki)) | F37: =IF(D37="","",IFERROR(INDEX(RelKm,MATCH(D37,RelNazivi,0))*IF(E37="ena smer",1,2),"")) | G37: =IF(F37="","",ROUND(F37*$J$3,2))
B38: =IF(WORKDAY(DATE(Leto,1,1)-1,29,Prazniki)>EOMONTH(DATE(Leto,1,1),0),"",WORKDAY(DATE(Leto,1,1)-1,29,Prazniki)) | F38: =IF(D38="","",IFERROR(INDEX(RelKm,MATCH(D38,RelNazivi,0))*IF(E38="ena smer",1,2),"")) | G38: =IF(F38="","",ROUND(F38*$J$3,2))
B39: =IF(WORKDAY(DATE(Leto,1,1)-1,30,Prazniki)>EOMONTH(DATE(Leto,1,1),0),"",WORKDAY(DATE(Leto,1,1)-1,30,Prazniki)) | F39: =IF(D39="","",IFERROR(INDEX(RelKm,MATCH(D39,RelNazivi,0))*IF(E39="ena smer",1,2),"")) | G39: =IF(F39="","",ROUND(F39*$J$3,2))
B40: =IF(WORKDAY(DATE(Leto,1,1)-1,31,Prazniki)>EOMONTH(DATE(Leto,1,1),0),"",WORKDAY(DATE(Leto,1,1)-1,31,Prazniki)) | F40: =IF(D40="","",IFERROR(INDEX(RelKm,MATCH(D40,RelNazivi,0))*IF(E40="ena smer",1,2),"")) | G40: =IF(F40="","",ROUND(F40*$J$3,2))
B41: SKUPAJ | F41: =SUM(F10:F40) -> 0 | G41: =SUM(G10:G40) -> 0
B42: *relacija se vpisuje od enote, kjer opravljate delo, do enote, kjer se odvija dogodek (izbira s seznama na listu Relacije)
...

Sheet Februar
B1: PODPISNI LIST - KILOMETRINA SLUŽBENIH POTI
I2: kilometrina
B3: =Ime -> Ime Priimek | I3: € / km | J3: =INDEX(KmCene,MATCH(DATE(Leto,2,1),KmDatumi,1)) -> 0.43
B4: =DelovnoMesto -> Enota | I4: delovni dnevi | J4: =NETWORKDAYS(DATE(Leto,2,1),EOMONTH(DATE(Leto,2,1),0),Prazniki) -> 20
B5: =DATE(Leto,2,1) -> 46054
B6: =Enote -> PALČEK, KRIŽE, DETELJICA, LOM, KOVOR
B9: DATUM | C9: DOGODEK / NAMEN POTI | D9: RELACIJA* | E9: POT | F9: KILOMETRI | G9: VREDNOST**
B10: =IF(WORKDAY(DATE(Leto,2,1)-1,1,Prazniki)>EOMONTH(DATE(Leto,2,1),0),"",WORKDAY(DATE(Leto,2,1)-1,1,Prazniki)) -> 46055 | F10: =IF(D10="","",IFERROR(INDEX(RelKm,MATCH(D10,RelNazivi,0))*IF(E10="ena smer",1,2),"")) | G10: =IF(F10="","",ROUND(F10*$J$3,2))
B11: =IF(WORKDAY(DATE(Leto,2,1)-1,2,Prazniki)>EOMONTH(DATE(Leto,2,1),0),"",WORKDAY(DATE(Leto,2,1)-1,2,Prazniki)) -> 46056 | F11: =IF(D11="","",IFERROR(INDEX(RelKm,MATCH(D11,RelNazivi,0))*IF(E11="ena smer",1,2),"")) | G11: =IF(F11="","",ROUND(F11*$J$3,2))
B12: =IF(WORKDAY(DATE(Leto,2,1)-1,3,Prazniki)>EOMONTH(DATE(Leto,2,1),0),"",WORKDAY(DATE(Leto,2,1)-1,3,Prazniki)) -> 46057 | F12: =IF(D12="","",IFERROR(INDEX(RelKm,MATCH(D12,RelNazivi,0))*IF(E12="ena smer",1,2),"")) | G12: =IF(F12="","",ROUND(F12*$J$3,2))
B13: =IF(WORKDAY(DATE(Leto,2,1)-1,4,Prazniki)>EOMONTH(DATE(Leto,2,1),0),"",WORKDAY(DATE(Leto,2,1)-1,4,Prazniki)) -> 46058 | F13: =IF(D13="","",IFERROR(INDEX(RelKm,MATCH(D13,RelNazivi,0))*IF(E13="ena smer",1,2),"")) | G13: =IF(F13="","",ROUND(F13*$J$3,2))
B14: =IF(WORKDAY(DATE(Leto,2,1)-1,5,Prazniki)>EOMONTH(DATE(Leto,2,1),0),"",WORKDAY(DATE(Leto,2,1)-1,5,Prazniki)) -> 46059 | F14: =IF(D14="","",IFERROR(INDEX(RelKm,MATCH(D14,RelNazivi,0))*IF(E14="ena smer",1,2),"")) | G14: =IF(F14="","",ROUND(F14*$J$3,2))
B15: =IF(WORKDAY(DATE(Leto,2,1)-1,6,Prazniki)>EOMONTH(DATE(Leto,2,1),0),"",WORKDAY(DATE(Leto,2,1)-1,6,Prazniki)) -> 46062 | F15: =IF(D15="","",IFERROR(INDEX(RelKm,MATCH(D15,RelNazivi,0))*IF(E15="ena smer",1,2),"")) | G15: =IF(F15="","",ROUND(F15*$J$3,2))
B16: =IF(WORKDAY(DATE(Leto,2,1)-1,7,Prazniki)>EOMONTH(DATE(Leto,2,1),0),"",WORKDAY(DATE(Leto,2,1)-1,7,Prazniki)) -> 46063 | F16: =IF(D16="","",IFERROR(INDEX(RelKm,MATCH(D16,RelNazivi,0))*IF(E16="ena smer",1,2),"")) | G16: =IF(F16="","",ROUND(F16*$J$3,2))
B17: =IF(WORKDAY(DATE(Leto,2,1)-1,8,Prazniki)>EOMONTH(DATE(Leto,2,1),0),"",WORKDAY(DATE(Leto,2,1)-1,8,Prazniki)) -> 46064 | F17: =IF(D17="","",IFERROR(INDEX(RelKm,MATCH(D17,RelNazivi,0))*IF(E17="ena smer",1,2),"")) | G17: =IF(F17="","",ROUND(F17*$J$3,2))
B18: =IF(WORKDAY(DATE(Leto,2,1)-1,9,Prazniki)>EOMONTH(DATE(Leto,2,1),0),"",WORKDAY(DATE(Leto,2,1)-1,9,Prazniki)) -> 46065 | F18: =IF(D18="","",IFERROR(INDEX(RelKm,MATCH(D18,RelNazivi,0))*IF(E18="ena smer",1,2),"")) | G18: =IF(F18="","",ROUND(F18*$J$3,2))
B19: =IF(WORKDAY(DATE(Leto,2,1)-1,10,Prazniki)>EOMONTH(DATE(Leto,2,1),0),"",WORKDAY(DATE(Leto,2,1)-1,10,Prazniki)) -> 46066 | F19: =IF(D19="","",IFERROR(INDEX(RelKm,MATCH(D19,RelNazivi,0))*IF(E19="ena smer",1,2),"")) | G19: =IF(F19="","",ROUND(F19*$J$3,2))
B20: =IF(WORKDAY(DATE(Leto,2,1)-1,11,Prazniki)>EOMONTH(DATE(Leto,2,1),0),"",WORKDAY(DATE(Leto,2,1)-1,11,Prazniki)) -> 46069 | F20: =IF(D20="","",IFERROR(INDEX(RelKm,MATCH(D20,RelNazivi,0))*IF(E20="ena smer",1,2),"")) | G20: =IF(F20="","",ROUND(F20*$J$3,2))
B21: =IF(WORKDAY(DATE(Leto,2,1)-1,12,Prazniki)>EOMONTH(DATE(Leto,2,1),0),"",WORKDAY(DATE(Leto,2,1)-1,12,Prazniki)) -> 46070 | F21: =IF(D21="","",IFERROR(INDEX(RelKm,MATCH(D21,RelNazivi,0))*IF(E21="ena smer",1,2),"")) | G21: =IF(F21="","",ROUND(F21*$J$3,2))
B22: =IF(WORKDAY(DATE(Leto,2,1)-1,13,Prazniki)>EOMONTH(DATE(Leto,2,1),0),"",WORKDAY(DATE(Leto,2,1)-1,13,Prazniki)) -> 46071 | F22: =IF(D22="","",IFERROR(INDEX(RelKm,MATCH(D22,RelNazivi,0))*IF(E22="ena smer",1,2),"")) | G22: =IF(F22="","",ROUND(F22*$J$3,2))
B23: =IF(WORKDAY(DATE(Leto,2,1)-1,14,Prazniki)>EOMONTH(DATE(Leto,2,1),0),"",WORKDAY(DATE(Leto,2,1)-1,14,Prazniki)) -> 46072 | F23: =IF(D23="","",IFERROR(INDEX(RelKm,MATCH(D23,RelNazivi,0))*IF(E23="ena smer",1,2),"")) | G23: =IF(F23="","",ROUND(F23*$J$3,2))
B24: =IF(WORKDAY(DATE(Leto,2,1)-1,15,Prazniki)>EOMONTH(DATE(Leto,2,1),0),"",WORKDAY(DATE(Leto,2,1)-1,15,Prazniki)) -> 46073 | F24: =IF(D24="","",IFERROR(INDEX(RelKm,MATCH(D24,RelNazivi,0))*IF(E24="ena smer",1,2),"")) | G24: =IF(F24="","",ROUND(F24*$J$3,2))
B25: =IF(WORKDAY(DATE(Leto,2,1)-1,16,Prazniki)>EOMONTH(DATE(Leto,2,1),0),"",WORKDAY(DATE(Leto,2,1)-1,16,Prazniki)) -> 46076 | F25: =IF(D25="","",IFERROR(INDEX(RelKm,MATCH(D25,RelNazivi,0))*IF(E25="ena smer",1,2),"")) | G25: =IF(F25="","",ROUND(F25*$J$3,2))
B26: =IF(WORKDAY(DATE(Leto,2,1)-1,17,Prazniki)>EOMONTH(DATE(Leto,2,1),0),"",WORKDAY(DATE(Leto,2,1)-1,17,Prazniki)) -> 46077 | F26: =IF(D26="","",IFERROR(INDEX(RelKm,MATCH(D26,RelNazivi,0))*IF(E26="ena smer",1,2),"")) | G26: =IF(F26="","",ROUND(F26*$J$3,2))
B27: =IF(WORKDAY(DATE(Leto,2,1)-1,18,Prazniki)>EOMONTH(DATE(Leto,2,1),0),"",WORKDAY(DATE(Leto,2,1)-1,18,Prazniki)) -> 46078 | F27: =IF(D27="","",IFERROR(INDEX(RelKm,MATCH(D27,RelNazivi,0))*IF(E27="ena smer",1,2),"")) | G27: =IF(F27="","",ROUND(F27*$J$3,2))
B28: =IF(WORKDAY(DATE(Leto,2,1)-1,19,Prazniki)>EOMONTH(DATE(Leto,2,1),0),"",WORKDAY(DATE(Leto,2,1)-1,19,Prazniki)) -> 46079 | F28: =IF(D28="","",IFERROR(INDEX(RelKm,MATCH(D28,RelNazivi,0))*IF(E28="ena smer",1,2),"")) | G28: =IF(F28="","",ROUND(F28*$J$3,2))
B29: =IF(WORKDAY(DATE(Leto,2,1)-1,20,Prazniki)>EOMONTH(DATE(Leto,2,1),0),"",WORKDAY(DATE(Leto,2,1)-1,20,Prazniki)) -> 46080 | F29: =IF(D29="","",IFERROR(INDEX(RelKm,MATCH(D29,RelNazivi,0))*IF(E29="ena smer",1,2),"")) | G29: =IF(F29="","",ROUND(F29*$J$3,2))
B30: =IF(WORKDAY(DATE(Leto,2,1)-1,21,Prazniki)>EOMONTH(DATE(Leto,2,1),0),"",WORKDAY(DATE(Leto,2,1)-1,21,Prazniki)) | F30: =IF(D30="","",IFERROR(INDEX(RelKm,MATCH(D30,RelNazivi,0))*IF(E30="ena smer",1,2),"")) | G30: =IF(F30="","",ROUND(F30*$J$3,2))
B31: =IF(WORKDAY(DATE(Leto,2,1)-1,22,Prazniki)>EOMONTH(DATE(Leto,2,1),0),"",WORKDAY(DATE(Leto,2,1)-1,22,Prazniki)) | F31: =IF(D31="","",IFERROR(INDEX(RelKm,MATCH(D31,RelNazivi,0))*IF(E31="ena smer",1,2),"")) | G31: =IF(F31="","",ROUND(F31*$J$3,2))
B32: =IF(WORKDAY(DATE(Leto,2,1)-1,23,Prazniki)>EOMONTH(DATE(Leto,2,1),0),"",WORKDAY(DATE(Leto,2,1)-1,23,Prazniki)) | F32: =IF(D32="","",IFERROR(INDEX(RelKm,MATCH(D32,RelNazivi,0))*IF(E32="ena smer",1,2),"")) | G32: =IF(F32="","",ROUND(F32*$J$3,2))
B33: =IF(WORKDAY(DATE(Leto,2,1)-1,24,Prazniki)>EOMONTH(DATE(Leto,2,1),0),"",WORKDAY(DATE(Leto,2,1)-1,24,Prazniki)) | F33: =IF(D33="","",IFERROR(INDEX(RelKm,MATCH(D33,RelNazivi,0))*IF(E33="ena smer",1,2),"")) | G33: =IF(F33="","",ROUND(F33*$J$3,2))
B34: =IF(WORKDAY(DATE(Leto,2,1)-1,25,Prazniki)>EOMONTH(DATE(Leto,2,1),0),"",WORKDAY(DATE(Leto,2,1)-1,25,Prazniki)) | F34: =IF(D34="","",IFERROR(INDEX(RelKm,MATCH(D34,RelNazivi,0))*IF(E34="ena smer",1,2),"")) | G34: =IF(F34="","",ROUND(F34*$J$3,2))
B35: =IF(WORKDAY(DATE(Leto,2,1)-1,26,Prazniki)>EOMONTH(DATE(Leto,2,1),0),"",WORKDAY(DATE(Leto,2,1)-1,26,Prazniki)) | F35: =IF(D35="","",IFERROR(INDEX(RelKm,MATCH(D35,RelNazivi,0))*IF(E35="ena smer",1,2),"")) | G35: =IF(F35="","",ROUND(F35*$J$3,2))
B36: =IF(WORKDAY(DATE(Leto,2,1)-1,27,Prazniki)>EOMONTH(DATE(Leto,2,1),0),"",WORKDAY(DATE(Leto,2,1)-1,27,Prazniki)) | F36: =IF(D36="","",IFERROR(INDEX(RelKm,MATCH(D36,RelNazivi,0))*IF(E36="ena smer",1,2),"")) | G36: =IF(F36="","",ROUND(F36*$J$3,2))
B37: =IF(WORKDAY(DATE(Leto,2,1)-1,28,Prazniki)>EOMONTH(DATE(Leto,2,1),0),"",WORKDAY(DATE(Leto,2,1)-1,28,Prazniki)) | F37: =IF(D37="","",IFERROR(INDEX(RelKm,MATCH(D37,RelNazivi,0))*IF(E37="ena smer",1,2),"")) | G37: =IF(F37="","",ROUND(F37*$J$3,2))
B38: =IF(WORKDAY(DATE(Leto,2,1)-1,29,Prazniki)>EOMONTH(DATE(Leto,2,1),0),"",WORKDAY(DATE(Leto,2,1)-1,29,Prazniki)) | F38: =IF(D38="","",IFERROR(INDEX(RelKm,MATCH(D38,RelNazivi,0))*IF(E38="ena smer",1,2),"")) | G38: =IF(F38="","",ROUND(F38*$J$3,2))
B39: =IF(WORKDAY(DATE(Leto,2,1)-1,30,Prazniki)>EOMONTH(DATE(Leto,2,1),0),"",WORKDAY(DATE(Leto,2,1)-1,30,Prazniki)) | F39: =IF(D39="","",IFERROR(INDEX(RelKm,MATCH(D39,RelNazivi,0))*IF(E39="ena smer",1,2),"")) | G39: =IF(F39="","",ROUND(F39*$J$3,2))
B40: =IF(WORKDAY(DATE(Leto,2,1)-1,31,Prazniki)>EOMONTH(DATE(Leto,2,1),0),"",WORKDAY(DATE(Leto,2,1)-1,31,Prazniki)) | F40: =IF(D40="","",IFERROR(INDEX(RelKm,MATCH(D40,RelNazivi,0))*IF(E40="ena smer",1,2),"")) | G40: =IF(F40="","",ROUND(F40*$J$3,2))
B41: SKUPAJ | F41: =SUM(F10:F40) -> 0 | G41: =SUM(G10:G40) -> 0
B42: *relacija se vpisuje od enote, kjer opravljate delo, do enote, kjer se odvija dogodek (izbira s seznama na listu Relacije)
...

Sheet Marec
B1: PODPISNI LIST - KILOMETRINA SLUŽBENIH POTI
I2: kilometrina
B3: =Ime -> Ime Priimek | I3: € / km | J3: =INDEX(KmCene,MATCH(DATE(Leto,3,1),KmDatumi,1)) -> 0.43
B4: =DelovnoMesto -> Enota | I4: delovni dnevi | J4: =NETWORKDAYS(DATE(Leto,3,1),EOMONTH(DATE(Leto,3,1),0),Prazniki) -> 22
B5: =DATE(Leto,3,1) -> 46082
B6: =Enote -> PALČEK, KRIŽE, DETELJICA, LOM, KOVOR
B9: DATUM | C9: DOGODEK / NAMEN POTI | D9: RELACIJA* | E9: POT | F9: KILOMETRI | G9: VREDNOST**
B10: =IF(WORKDAY(DATE(Leto,3,1)-1,1,Prazniki)>EOMONTH(DATE(Leto,3,1),0),"",WORKDAY(DATE(Leto,3,1)-1,1,Prazniki)) -> 46083 | F10: =IF(D10="","",IFERROR(INDEX(RelKm,MATCH(D10,RelNazivi,0))*IF(E10="ena smer",1,2),"")) | G10: =IF(F10="","",ROUND(F10*$J$3,2))
B11: =IF(WORKDAY(DATE(Leto,3,1)-1,2,Prazniki)>EOMONTH(DATE(Leto,3,1),0),"",WORKDAY(DATE(Leto,3,1)-1,2,Prazniki)) -> 46084 | F11: =IF(D11="","",IFERROR(INDEX(RelKm,MATCH(D11,RelNazivi,0))*IF(E11="ena smer",1,2),"")) | G11: =IF(F11="","",ROUND(F11*$J$3,2))
B12: =IF(WORKDAY(DATE(Leto,3,1)-1,3,Prazniki)>EOMONTH(DATE(Leto,3,1),0),"",WORKDAY(DATE(Leto,3,1)-1,3,Prazniki)) -> 46085 | F12: =IF(D12="","",IFERROR(INDEX(RelKm,MATCH(D12,RelNazivi,0))*IF(E12="ena smer",1,2),"")) | G12: =IF(F12="","",ROUND(F12*$J$3,2))
B13: =IF(WORKDAY(DATE(Leto,3,1)-1,4,Prazniki)>EOMONTH(DATE(Leto,3,1),0),"",WORKDAY(DATE(Leto,3,1)-1,4,Prazniki)) -> 46086 | F13: =IF(D13="","",IFERROR(INDEX(RelKm,MATCH(D13,RelNazivi,0))*IF(E13="ena smer",1,2),"")) | G13: =IF(F13="","",ROUND(F13*$J$3,2))
B14: =IF(WORKDAY(DATE(Leto,3,1)-1,5,Prazniki)>EOMONTH(DATE(Leto,3,1),0),"",WORKDAY(DATE(Leto,3,1)-1,5,Prazniki)) -> 46087 | F14: =IF(D14="","",IFERROR(INDEX(RelKm,MATCH(D14,RelNazivi,0))*IF(E14="ena smer",1,2),"")) | G14: =IF(F14="","",ROUND(F14*$J$3,2))
B15: =IF(WORKDAY(DATE(Leto,3,1)-1,6,Prazniki)>EOMONTH(DATE(Leto,3,1),0),"",WORKDAY(DATE(Leto,3,1)-1,6,Prazniki)) -> 46090 | F15: =IF(D15="","",IFERROR(INDEX(RelKm,MATCH(D15,RelNazivi,0))*IF(E15="ena smer",1,2),"")) | G15: =IF(F15="","",ROUND(F15*$J$3,2))
B16: =IF(WORKDAY(DATE(Leto,3,1)-1,7,Prazniki)>EOMONTH(DATE(Leto,3,1),0),"",WORKDAY(DATE(Leto,3,1)-1,7,Prazniki)) -> 46091 | F16: =IF(D16="","",IFERROR(INDEX(RelKm,MATCH(D16,RelNazivi,0))*IF(E16="ena smer",1,2),"")) | G16: =IF(F16="","",ROUND(F16*$J$3,2))
B17: =IF(WORKDAY(DATE(Leto,3,1)-1,8,Prazniki)>EOMONTH(DATE(Leto,3,1),0),"",WORKDAY(DATE(Leto,3,1)-1,8,Prazniki)) -> 46092 | F17: =IF(D17="","",IFERROR(INDEX(RelKm,MATCH(D17,RelNazivi,0))*IF(E17="ena smer",1,2),"")) | G17: =IF(F17="","",ROUND(F17*$J$3,2))
B18: =IF(WORKDAY(DATE(Leto,3,1)-1,9,Prazniki)>EOMONTH(DATE(Leto,3,1),0),"",WORKDAY(DATE(Leto,3,1)-1,9,Prazniki)) -> 46093 | F18: =IF(D18="","",IFERROR(INDEX(RelKm,MATCH(D18,RelNazivi,0))*IF(E18="ena smer",1,2),"")) | G18: =IF(F18="","",ROUND(F18*$J$3,2))
B19: =IF(WORKDAY(DATE(Leto,3,1)-1,10,Prazniki)>EOMONTH(DATE(Leto,3,1),0),"",WORKDAY(DATE(Leto,3,1)-1,10,Prazniki)) -> 46094 | F19: =IF(D19="","",IFERROR(INDEX(RelKm,MATCH(D19,RelNazivi,0))*IF(E19="ena smer",1,2),"")) | G19: =IF(F19="","",ROUND(F19*$J$3,2))
B20: =IF(WORKDAY(DATE(Leto,3,1)-1,11,Prazniki)>EOMONTH(DATE(Leto,3,1),0),"",WORKDAY(DATE(Leto,3,1)-1,11,Prazniki)) -> 46097 | F20: =IF(D20="","",IFERROR(INDEX(RelKm,MATCH(D20,RelNazivi,0))*IF(E20="ena smer",1,2),"")) | G20: =IF(F20="","",ROUND(F20*$J$3,2))
B21: =IF(WORKDAY(DATE(Leto,3,1)-1,12,Prazniki)>EOMONTH(DATE(Leto,3,1),0),"",WORKDAY(DATE(Leto,3,1)-1,12,Prazniki)) -> 46098 | F21: =IF(D21="","",IFERROR(INDEX(RelKm,MATCH(D21,RelNazivi,0))*IF(E21="ena smer",1,2),"")) | G21: =IF(F21="","",ROUND(F21*$J$3,2))
B22: =IF(WORKDAY(DATE(Leto,3,1)-1,13,Prazniki)>EOMONTH(DATE(Leto,3,1),0),"",WORKDAY(DATE(Leto,3,1)-1,13,Prazniki)) -> 46099 | F22: =IF(D22="","",IFERROR(INDEX(RelKm,MATCH(D22,RelNazivi,0))*IF(E22="ena smer",1,2),"")) | G22: =IF(F22="","",ROUND(F22*$J$3,2))
B23: =IF(WORKDAY(DATE(Leto,3,1)-1,14,Prazniki)>EOMONTH(DATE(Leto,3,1),0),"",WORKDAY(DATE(Leto,3,1)-1,14,Prazniki)) -> 46100 | F23: =IF(D23="","",IFERROR(INDEX(RelKm,MATCH(D23,RelNazivi,0))*IF(E23="ena smer",1,2),"")) | G23: =IF(F23="","",ROUND(F23*$J$3,2))
B24: =IF(WORKDAY(DATE(Leto,3,1)-1,15,Prazniki)>EOMONTH(DATE(Leto,3,1),0),"",WORKDAY(DATE(Leto,3,1)-1,15,Prazniki)) -> 46101 | F24: =IF(D24="","",IFERROR(INDEX(RelKm,MATCH(D24,RelNazivi,0))*IF(E24="ena smer",1,2),"")) | G24: =IF(F24="","",ROUND(F24*$J$3,2))
B25: =IF(WORKDAY(DATE(Leto,3,1)-1,16,Prazniki)>EOMONTH(DATE(Leto,3,1),0),"",WORKDAY(DATE(Leto,3,1)-1,16,Prazniki)) -> 46104 | F25: =IF(D25="","",IFERROR(INDEX(RelKm,MATCH(D25,RelNazivi,0))*IF(E25="ena smer",1,2),"")) | G25: =IF(F25="","",ROUND(F25*$J$3,2))
B26: =IF(WORKDAY(DATE(Leto,3,1)-1,17,Prazniki)>EOMONTH(DATE(Leto,3,1),0),"",WORKDAY(DATE(Leto,3,1)-1,17,Prazniki)) -> 46105 | F26: =IF(D26="","",IFERROR(INDEX(RelKm,MATCH(D26,RelNazivi,0))*IF(E26="ena smer",1,2),"")) | G26: =IF(F26="","",ROUND(F26*$J$3,2))
B27: =IF(WORKDAY(DATE(Leto,3,1)-1,18,Prazniki)>EOMONTH(DATE(Leto,3,1),0),"",WORKDAY(DATE(Leto,3,1)-1,18,Prazniki)) -> 46106 | F27: =IF(D27="","",IFERROR(INDEX(RelKm,MATCH(D27,RelNazivi,0))*IF(E27="ena smer",1,2),"")) | G27: =IF(F27="","",ROUND(F27*$J$3,2))
B28: =IF(WORKDAY(DATE(Leto,3,1)-1,19,Prazniki)>EOMONTH(DATE(Leto,3,1),0),"",WORKDAY(DATE(Leto,3,1)-1,19,Prazniki)) -> 46107 | F28: =IF(D28="","",IFERROR(INDEX(RelKm,MATCH(D28,RelNazivi,0))*IF(E28="ena smer",1,2),"")) | G28: =IF(F28="","",ROUND(F28*$J$3,2))
B29: =IF(WORKDAY(DATE(Leto,3,1)-1,20,Prazniki)>EOMONTH(DATE(Leto,3,1),0),"",WORKDAY(DATE(Leto,3,1)-1,20,Prazniki)) -> 46108 | F29: =IF(D29="","",IFERROR(INDEX(RelKm,MATCH(D29,RelNazivi,0))*IF(E29="ena smer",1,2),"")) | G29: =IF(F29="","",ROUND(F29*$J$3,2))
B30: =IF(WORKDAY(DATE(Leto,3,1)-1,21,Prazniki)>EOMONTH(DATE(Leto,3,1),0),"",WORKDAY(DATE(Leto,3,1)-1,21,Prazniki)) -> 46111 | F30: =IF(D30="","",IFERROR(INDEX(RelKm,MATCH(D30,RelNazivi,0))*IF(E30="ena smer",1,2),"")) | G30: =IF(F30="","",ROUND(F30*$J$3,2))
B31: =IF(WORKDAY(DATE(Leto,3,1)-1,22,Prazniki)>EOMONTH(DATE(Leto,3,1),0),"",WORKDAY(DATE(Leto,3,1)-1,22,Prazniki)) -> 46112 | F31: =IF(D31="","",IFERROR(INDEX(RelKm,MATCH(D31,RelNazivi,0))*IF(E31="ena smer",1,2),"")) | G31: =IF(F31="","",ROUND(F31*$J$3,2))
B32: =IF(WORKDAY(DATE(Leto,3,1)-1,23,Prazniki)>EOMONTH(DATE(Leto,3,1),0),"",WORKDAY(DATE(Leto,3,1)-1,23,Prazniki)) | F32: =IF(D32="","",IFERROR(INDEX(RelKm,MATCH(D32,RelNazivi,0))*IF(E32="ena smer",1,2),"")) | G32: =IF(F32="","",ROUND(F32*$J$3,2))
B33: =IF(WORKDAY(DATE(Leto,3,1)-1,24,Prazniki)>EOMONTH(DATE(Leto,3,1),0),"",WORKDAY(DATE(Leto,3,1)-1,24,Prazniki)) | F33: =IF(D33="","",IFERROR(INDEX(RelKm,MATCH(D33,RelNazivi,0))*IF(E33="ena smer",1,2),"")) | G33: =IF(F33="","",ROUND(F33*$J$3,2))
B34: =IF(WORKDAY(DATE(Leto,3,1)-1,25,Prazniki)>EOMONTH(DATE(Leto,3,1),0),"",WORKDAY(DATE(Leto,3,1)-1,25,Prazniki)) | F34: =IF(D34="","",IFERROR(INDEX(RelKm,MATCH(D34,RelNazivi,0))*IF(E34="ena smer",1,2),"")) | G34: =IF(F34="","",ROUND(F34*$J$3,2))
B35: =IF(WORKDAY(DATE(Leto,3,1)-1,26,Prazniki)>EOMONTH(DATE(Leto,3,1),0),"",WORKDAY(DATE(Leto,3,1)-1,26,Prazniki)) | F35: =IF(D35="","",IFERROR(INDEX(RelKm,MATCH(D35,RelNazivi,0))*IF(E35="ena smer",1,2),"")) | G35: =IF(F35="","",ROUND(F35*$J$3,2))
B36: =IF(WORKDAY(DATE(Leto,3,1)-1,27,Prazniki)>EOMONTH(DATE(Leto,3,1),0),"",WORKDAY(DATE(Leto,3,1)-1,27,Prazniki)) | F36: =IF(D36="","",IFERROR(INDEX(RelKm,MATCH(D36,RelNazivi,0))*IF(E36="ena smer",1,2),"")) | G36: =IF(F36="","",ROUND(F36*$J$3,2))
B37: =IF(WORKDAY(DATE(Leto,3,1)-1,28,Prazniki)>EOMONTH(DATE(Leto,3,1),0),"",WORKDAY(DATE(Leto,3,1)-1,28,Prazniki)) | F37: =IF(D37="","",IFERROR(INDEX(RelKm,MATCH(D37,RelNazivi,0))*IF(E37="ena smer",1,2),"")) | G37: =IF(F37="","",ROUND(F37*$J$3,2))
B38: =IF(WORKDAY(DATE(Leto,3,1)-1,29,Prazniki)>EOMONTH(DATE(Leto,3,1),0),"",WORKDAY(DATE(Leto,3,1)-1,29,Prazniki)) | F38: =IF(D38="","",IFERROR(INDEX(RelKm,MATCH(D38,RelNazivi,0))*IF(E38="ena smer",1,2),"")) | G38: =IF(F38="","",ROUND(F38*$J$3,2))
B39: =IF(WORKDAY(DATE(Leto,3,1)-1,30,Prazniki)>EOMONTH(DATE(Leto,3,1),0),"",WORKDAY(DATE(Leto,3,1)-1,30,Prazniki)) | F39: =IF(D39="","",IFERROR(INDEX(RelKm,MATCH(D39,RelNazivi,0))*IF(E39="ena smer",1,2),"")) | G39: =IF(F39="","",ROUND(F39*$J$3,2))
B40: =IF(WORKDAY(DATE(Leto,3,1)-1,31,Prazniki)>EOMONTH(DATE(Leto,3,1),0),"",WORKDAY(DATE(Leto,3,1)-1,31,Prazniki)) | F40: =IF(D40="","",IFERROR(INDEX(RelKm,MATCH(D40,RelNazivi,0))*IF(E40="ena smer",1,2),"")) | G40: =IF(F40="","",ROUND(F40*$J$3,2))
B41: SKUPAJ | F41: =SUM(F10:F40) -> 0 | G41: =SUM(G10:G40) -> 0
B42: *relacija se vpisuje od enote, kjer opravljate delo, do enote, kjer se odvija dogodek (izbira s seznama na listu Relacije)
...

Sheet April
B1: PODPISNI LIST - KILOMETRINA SLUŽBENIH POTI
I2: kilometrina
B3: =Ime -> Ime Priimek | I3: € / km | J3: =INDEX(KmCene,MATCH(DATE(Leto,4,1),KmDatumi,1)) -> 0.43
B4: =DelovnoMesto -> Enota | I4: delovni dnevi | J4: =NETWORKDAYS(DATE(Leto,4,1),EOMONTH(DATE(Leto,4,1),0),Prazniki) -> 20
B5: =DATE(Leto,4,1) -> 46113
B6: =Enote -> PALČEK, KRIŽE, DETELJICA, LOM, KOVOR
B9: DATUM | C9: DOGODEK / NAMEN POTI | D9: RELACIJA* | E9: POT | F9: KILOMETRI | G9: VREDNOST**
B10: =IF(WORKDAY(DATE(Leto,4,1)-1,1,Prazniki)>EOMONTH(DATE(Leto,4,1),0),"",WORKDAY(DATE(Leto,4,1)-1,1,Prazniki)) -> 46113 | F10: =IF(D10="","",IFERROR(INDEX(RelKm,MATCH(D10,RelNazivi,0))*IF(E10="ena smer",1,2),"")) | G10: =IF(F10="","",ROUND(F10*$J$3,2))
B11: =IF(WORKDAY(DATE(Leto,4,1)-1,2,Prazniki)>EOMONTH(DATE(Leto,4,1),0),"",WORKDAY(DATE(Leto,4,1)-1,2,Prazniki)) -> 46114 | F11: =IF(D11="","",IFERROR(INDEX(RelKm,MATCH(D11,RelNazivi,0))*IF(E11="ena smer",1,2),"")) | G11: =IF(F11="","",ROUND(F11*$J$3,2))
B12: =IF(WORKDAY(DATE(Leto,4,1)-1,3,Prazniki)>EOMONTH(DATE(Leto,4,1),0),"",WORKDAY(DATE(Leto,4,1)-1,3,Prazniki)) -> 46115 | F12: =IF(D12="","",IFERROR(INDEX(RelKm,MATCH(D12,RelNazivi,0))*IF(E12="ena smer",1,2),"")) | G12: =IF(F12="","",ROUND(F12*$J$3,2))
B13: =IF(WORKDAY(DATE(Leto,4,1)-1,4,Prazniki)>EOMONTH(DATE(Leto,4,1),0),"",WORKDAY(DATE(Leto,4,1)-1,4,Prazniki)) -> 46119 | F13: =IF(D13="","",IFERROR(INDEX(RelKm,MATCH(D13,RelNazivi,0))*IF(E13="ena smer",1,2),"")) | G13: =IF(F13="","",ROUND(F13*$J$3,2))
B14: =IF(WORKDAY(DATE(Leto,4,1)-1,5,Prazniki)>EOMONTH(DATE(Leto,4,1),0),"",WORKDAY(DATE(Leto,4,1)-1,5,Prazniki)) -> 46120 | F14: =IF(D14="","",IFERROR(INDEX(RelKm,MATCH(D14,RelNazivi,0))*IF(E14="ena smer",1,2),"")) | G14: =IF(F14="","",ROUND(F14*$J$3,2))
B15: =IF(WORKDAY(DATE(Leto,4,1)-1,6,Prazniki)>EOMONTH(DATE(Leto,4,1),0),"",WORKDAY(DATE(Leto,4,1)-1,6,Prazniki)) -> 46121 | F15: =IF(D15="","",IFERROR(INDEX(RelKm,MATCH(D15,RelNazivi,0))*IF(E15="ena smer",1,2),"")) | G15: =IF(F15="","",ROUND(F15*$J$3,2))
B16: =IF(WORKDAY(DATE(Leto,4,1)-1,7,Prazniki)>EOMONTH(DATE(Leto,4,1),0),"",WORKDAY(DATE(Leto,4,1)-1,7,Prazniki)) -> 46122 | F16: =IF(D16="","",IFERROR(INDEX(RelKm,MATCH(D16,RelNazivi,0))*IF(E16="ena smer",1,2),"")) | G16: =IF(F16="","",ROUND(F16*$J$3,2))
B17: =IF(WORKDAY(DATE(Leto,4,1)-1,8,Prazniki)>EOMONTH(DATE(Leto,4,1),0),"",WORKDAY(DATE(Leto,4,1)-1,8,Prazniki)) -> 46125 | F17: =IF(D17="","",IFERROR(INDEX(RelKm,MATCH(D17,RelNazivi,0))*IF(E17="ena smer",1,2),"")) | G17: =IF(F17="","",ROUND(F17*$J$3,2))
B18: =IF(WORKDAY(DATE(Leto,4,1)-1,9,Prazniki)>EOMONTH(DATE(Leto,4,1),0),"",WORKDAY(DATE(Leto,4,1)-1,9,Prazniki)) -> 46126 | F18: =IF(D18="","",IFERROR(INDEX(RelKm,MATCH(D18,RelNazivi,0))*IF(E18="ena smer",1,2),"")) | G18: =IF(F18="","",ROUND(F18*$J$3,2))
B19: =IF(WORKDAY(DATE(Leto,4,1)-1,10,Prazniki)>EOMONTH(DATE(Leto,4,1),0),"",WORKDAY(DATE(Leto,4,1)-1,10,Prazniki)) -> 46127 | F19: =IF(D19="","",IFERROR(INDEX(RelKm,MATCH(D19,RelNazivi,0))*IF(E19="ena smer",1,2),"")) | G19: =IF(F19="","",ROUND(F19*$J$3,2))
B20: =IF(WORKDAY(DATE(Leto,4,1)-1,11,Prazniki)>EOMONTH(DATE(Leto,4,1),0),"",WORKDAY(DATE(Leto,4,1)-1,11,Prazniki)) -> 46128 | F20: =IF(D20="","",IFERROR(INDEX(RelKm,MATCH(D20,RelNazivi,0))*IF(E20="ena smer",1,2),"")) | G20: =IF(F20="","",ROUND(F20*$J$3,2))
B21: =IF(WORKDAY(DATE(Leto,4,1)-1,12,Prazniki)>EOMONTH(DATE(Leto,4,1),0),"",WORKDAY(DATE(Leto,4,1)-1,12,Prazniki)) -> 46129 | F21: =IF(D21="","",IFERROR(INDEX(RelKm,MATCH(D21,RelNazivi,0))*IF(E21="ena smer",1,2),"")) | G21: =IF(F21="","",ROUND(F21*$J$3,2))
B22: =IF(WORKDAY(DATE(Leto,4,1)-1,13,Prazniki)>EOMONTH(DATE(Leto,4,1),0),"",WORKDAY(DATE(Leto,4,1)-1,13,Prazniki)) -> 46132 | F22: =IF(D22="","",IFERROR(INDEX(RelKm,MATCH(D22,RelNazivi,0))*IF(E22="ena smer",1,2),"")) | G22: =IF(F22="","",ROUND(F22*$J$3,2))
B23: =IF(WORKDAY(DATE(Leto,4,1)-1,14,Prazniki)>EOMONTH(DATE(Leto,4,1),0),"",WORKDAY(DATE(Leto,4,1)-1,14,Prazniki)) -> 46133 | F23: =IF(D23="","",IFERROR(INDEX(RelKm,MATCH(D23,RelNazivi,0))*IF(E23="ena smer",1,2),"")) | G23: =IF(F23="","",ROUND(F23*$J$3,2))
B24: =IF(WORKDAY(DATE(Leto,4,1)-1,15,Prazniki)>EOMONTH(DATE(Leto,4,1),0),"",WORKDAY(DATE(Leto,4,1)-1,15,Prazniki)) -> 46134 | F24: =IF(D24="","",IFERROR(INDEX(RelKm,MATCH(D24,RelNazivi,0))*IF(E24="ena smer",1,2),"")) | G24: =IF(F24="","",ROUND(F24*$J$3,2))
B25: =IF(WORKDAY(DATE(Leto,4,1)-1,16,Prazniki)>EOMONTH(DATE(Leto,4,1),0),"",WORKDAY(DATE(Leto,4,1)-1,16,Prazniki)) -> 46135 | F25: =IF(D25="","",IFERROR(INDEX(RelKm,MATCH(D25,RelNazivi,0))*IF(E25="ena smer",1,2),"")) | G25: =IF(F25="","",ROUND(F25*$J$3,2))
B26: =IF(WORKDAY(DATE(Leto,4,1)-1,17,Prazniki)>EOMONTH(DATE(Leto,4,1),0),"",WORKDAY(DATE(Leto,4,1)-1,17,Prazniki)) -> 46136 | F26: =IF(D26="","",IFERROR(INDEX(RelKm,MATCH(D26,RelNazivi,0))*IF(E26="ena smer",1,2),"")) | G26: =IF(F26="","",ROUND(F26*$J$3,2))
B27: =IF(WORKDAY(DATE(Leto,4,1)-1,18,Prazniki)>EOMONTH(DATE(Leto,4,1),0),"",WORKDAY(DATE(Leto,4,1)-1,18,Prazniki)) -> 46140 | F27: =IF(D27="","",IFERROR(INDEX(RelKm,MATCH(D27,RelNazivi,0))*IF(E27="ena smer",1,2),"")) | G27: =IF(F27="","",ROUND(F27*$J$3,2))
B28: =IF(WORKDAY(DATE(Leto,4,1)-1,19,Prazniki)>EOMONTH(DATE(Leto,4,1),0),"",WORKDAY(DATE(Leto,4,1)-1,19,Prazniki)) -> 46141 | F28: =IF(D28="","",IFERROR(INDEX(RelKm,MATCH(D28,RelNazivi,0))*IF(E28="ena smer",1,2),"")) | G28: =IF(F28="","",ROUND(F28*$J$3,2))
B29: =IF(WORKDAY(DATE(Leto,4,1)-1,20,Prazniki)>EOMONTH(DATE(Leto,4,1),0),"",WORKDAY(DATE(Leto,4,1)-1,20,Prazniki)) -> 46142 | F29: =IF(D29="","",IFERROR(INDEX(RelKm,MATCH(D29,RelNazivi,0))*IF(E29="ena smer",1,2),"")) | G29: =IF(F29="","",ROUND(F29*$J$3,2))
B30: =IF(WORKDAY(DATE(Leto,4,1)-1,21,Prazniki)>EOMONTH(DATE(Leto,4,1),0),"",WORKDAY(DATE(Leto,4,1)-1,21,Prazniki)) | F30: =IF(D30="","",IFERROR(INDEX(RelKm,MATCH(D30,RelNazivi,0))*IF(E30="ena smer",1,2),"")) | G30: =IF(F30="","",ROUND(F30*$J$3,2))
B31: =IF(WORKDAY(DATE(Leto,4,1)-1,22,Prazniki)>EOMONTH(DATE(Leto,4,1),0),"",WORKDAY(DATE(Leto,4,1)-1,22,Prazniki)) | F31: =IF(D31="","",IFERROR(INDEX(RelKm,MATCH(D31,RelNazivi,0))*IF(E31="ena smer",1,2),"")) | G31: =IF(F31="","",ROUND(F31*$J$3,2))
B32: =IF(WORKDAY(DATE(Leto,4,1)-1,23,Prazniki)>EOMONTH(DATE(Leto,4,1),0),"",WORKDAY(DATE(Leto,4,1)-1,23,Prazniki)) | F32: =IF(D32="","",IFERROR(INDEX(RelKm,MATCH(D32,RelNazivi,0))*IF(E32="ena smer",1,2),"")) | G32: =IF(F32="","",ROUND(F32*$J$3,2))
B33: =IF(WORKDAY(DATE(Leto,4,1)-1,24,Prazniki)>EOMONTH(DATE(Leto,4,1),0),"",WORKDAY(DATE(Leto,4,1)-1,24,Prazniki)) | F33: =IF(D33="","",IFERROR(INDEX(RelKm,MATCH(D33,RelNazivi,0))*IF(E33="ena smer",1,2),"")) | G33: =IF(F33="","",ROUND(F33*$J$3,2))
B34: =IF(WORKDAY(DATE(Leto,4,1)-1,25,Prazniki)>EOMONTH(DATE(Leto,4,1),0),"",WORKDAY(DATE(Leto,4,1)-1,25,Prazniki)) | F34: =IF(D34="","",IFERROR(INDEX(RelKm,MATCH(D34,RelNazivi,0))*IF(E34="ena smer",1,2),"")) | G34: =IF(F34="","",ROUND(F34*$J$3,2))
B35: =IF(WORKDAY(DATE(Leto,4,1)-1,26,Prazniki)>EOMONTH(DATE(Leto,4,1),0),"",WORKDAY(DATE(Leto,4,1)-1,26,Prazniki)) | F35: =IF(D35="","",IFERROR(INDEX(RelKm,MATCH(D35,RelNazivi,0))*IF(E35="ena smer",1,2),"")) | G35: =IF(F35="","",ROUND(F35*$J$3,2))
B36: =IF(WORKDAY(DATE(Leto,4,1)-1,27,Prazniki)>EOMONTH(DATE(Leto,4,1),0),"",WORKDAY(DATE(Leto,4,1)-1,27,Prazniki)) | F36: =IF(D36="","",IFERROR(INDEX(RelKm,MATCH(D36,RelNazivi,0))*IF(E36="ena smer",1,2),"")) | G36: =IF(F36="","",ROUND(F36*$J$3,2))
B37: =IF(WORKDAY(DATE(Leto,4,1)-1,28,Prazniki)>EOMONTH(DATE(Leto,4,1),0),"",WORKDAY(DATE(Leto,4,1)-1,28,Prazniki)) | F37: =IF(D37="","",IFERROR(INDEX(RelKm,MATCH(D37,RelNazivi,0))*IF(E37="ena smer",1,2),"")) | G37: =IF(F37="","",ROUND(F37*$J$3,2))
B38: =IF(WORKDAY(DATE(Leto,4,1)-1,29,Prazniki)>EOMONTH(DATE(Leto,4,1),0),"",WORKDAY(DATE(Leto,4,1)-1,29,Prazniki)) | F38: =IF(D38="","",IFERROR(INDEX(RelKm,MATCH(D38,RelNazivi,0))*IF(E38="ena smer",1,2),"")) | G38: =IF(F38="","",ROUND(F38*$J$3,2))
B39: =IF(WORKDAY(DATE(Leto,4,1)-1,30,Prazniki)>EOMONTH(DATE(Leto,4,1),0),"",WORKDAY(DATE(Leto,4,1)-1,30,Prazniki)) | F39: =IF(D39="","",IFERROR(INDEX(RelKm,MATCH(D39,RelNazivi,0))*IF(E39="ena smer",1,2),"")) | G39: =IF(F39="","",ROUND(F39*$J$3,2))
B40: =IF(WORKDAY(DATE(Leto,4,1)-1,31,Prazniki)>EOMONTH(DATE(Leto,4,1),0),"",WORKDAY(DATE(Leto,4,1)-1,31,Prazniki)) | F40: =IF(D40="","",IFERROR(INDEX(RelKm,MATCH(D40,RelNazivi,0))*IF(E40="ena smer",1,2),"")) | G40: =IF(F40="","",ROUND(F40*$J$3,2))
B41: SKUPAJ | F41: =SUM(F10:F40) -> 0 | G41: =SUM(G10:G40) -> 0
B42: *relacija se vpisuje od enote, kjer opravljate delo, do enote, kjer se odvija dogodek (izbira s seznama na listu Relacije)
...

Sheet Maj
B1: PODPISNI LIST - KILOMETRINA SLUŽBENIH POTI
I2: kilometrina
B3: =Ime -> Ime Priimek | I3: € / km | J3: =INDEX(KmCene,MATCH(DATE(Leto,5,1),KmDatumi,1)) -> 0.43
B4: =DelovnoMesto -> Enota | I4: delovni dnevi | J4: =NETWORKDAYS(DATE(Leto,5,1),EOMONTH(DATE(Leto,5,1),0),Prazniki) -> 20
B5: =DATE(Leto,5,1) -> 46143
B6: =Enote -> PALČEK, KRIŽE, DETELJICA, LOM, KOVOR
B9: DATUM | C9: DOGODEK / NAMEN POTI | D9: RELACIJA* | E9: POT | F9: KILOMETRI | G9: VREDNOST**
B10: =IF(WORKDAY(DATE(Leto,5,1)-1,1,Prazniki)>EOMONTH(DATE(Leto,5,1),0),"",WORKDAY(DATE(Leto,5,1)-1,1,Prazniki)) -> 46146 | F10: =IF(D10="","",IFERROR(INDEX(RelKm,MATCH(D10,RelNazivi,0))*IF(E10="ena smer",1,2),"")) | G10: =IF(F10="","",ROUND(F10*$J$3,2))
B11: =IF(WORKDAY(DATE(Leto,5,1)-1,2,Prazniki)>EOMONTH(DATE(Leto,5,1),0),"",WORKDAY(DATE(Leto,5,1)-1,2,Prazniki)) -> 46147 | F11: =IF(D11="","",IFERROR(INDEX(RelKm,MATCH(D11,RelNazivi,0))*IF(E11="ena smer",1,2),"")) | G11: =IF(F11="","",ROUND(F11*$J$3,2))
B12: =IF(WORKDAY(DATE(Leto,5,1)-1,3,Prazniki)>EOMONTH(DATE(Leto,5,1),0),"",WORKDAY(DATE(Leto,5,1)-1,3,Prazniki)) -> 46148 | F12: =IF(D12="","",IFERROR(INDEX(RelKm,MATCH(D12,RelNazivi,0))*IF(E12="ena smer",1,2),"")) | G12: =IF(F12="","",ROUND(F12*$J$3,2))
B13: =IF(WORKDAY(DATE(Leto,5,1)-1,4,Prazniki)>EOMONTH(DATE(Leto,5,1),0),"",WORKDAY(DATE(Leto,5,1)-1,4,Prazniki)) -> 46149 | F13: =IF(D13="","",IFERROR(INDEX(RelKm,MATCH(D13,RelNazivi,0))*IF(E13="ena smer",1,2),"")) | G13: =IF(F13="","",ROUND(F13*$J$3,2))
B14: =IF(WORKDAY(DATE(Leto,5,1)-1,5,Prazniki)>EOMONTH(DATE(Leto,5,1),0),"",WORKDAY(DATE(Leto,5,1)-1,5,Prazniki)) -> 46150 | F14: =IF(D14="","",IFERROR(INDEX(RelKm,MATCH(D14,RelNazivi,0))*IF(E14="ena smer",1,2),"")) | G14: =IF(F14="","",ROUND(F14*$J$3,2))
B15: =IF(WORKDAY(DATE(Leto,5,1)-1,6,Prazniki)>EOMONTH(DATE(Leto,5,1),0),"",WORKDAY(DATE(Leto,5,1)-1,6,Prazniki)) -> 46153 | F15: =IF(D15="","",IFERROR(INDEX(RelKm,MATCH(D15,RelNazivi,0))*IF(E15="ena smer",1,2),"")) | G15: =IF(F15="","",ROUND(F15*$J$3,2))
B16: =IF(WORKDAY(DATE(Leto,5,1)-1,7,Prazniki)>EOMONTH(DATE(Leto,5,1),0),"",WORKDAY(DATE(Leto,5,1)-1,7,Prazniki)) -> 46154 | F16: =IF(D16="","",IFERROR(INDEX(RelKm,MATCH(D16,RelNazivi,0))*IF(E16="ena smer",1,2),"")) | G16: =IF(F16="","",ROUND(F16*$J$3,2))
B17: =IF(WORKDAY(DATE(Leto,5,1)-1,8,Prazniki)>EOMONTH(DATE(Leto,5,1),0),"",WORKDAY(DATE(Leto,5,1)-1,8,Prazniki)) -> 46155 | F17: =IF(D17="","",IFERROR(INDEX(RelKm,MATCH(D17,RelNazivi,0))*IF(E17="ena smer",1,2),"")) | G17: =IF(F17="","",ROUND(F17*$J$3,2))
B18: =IF(WORKDAY(DATE(Leto,5,1)-1,9,Prazniki)>EOMONTH(DATE(Leto,5,1),0),"",WORKDAY(DATE(Leto,5,1)-1,9,Prazniki)) -> 46156 | F18: =IF(D18="","",IFERROR(INDEX(RelKm,MATCH(D18,RelNazivi,0))*IF(E18="ena smer",1,2),"")) | G18: =IF(F18="","",ROUND(F18*$J$3,2))
B19: =IF(WORKDAY(DATE(Leto,5,1)-1,10,Prazniki)>EOMONTH(DATE(Leto,5,1),0),"",WORKDAY(DATE(Leto,5,1)-1,10,Prazniki)) -> 46157 | F19: =IF(D19="","",IFERROR(INDEX(RelKm,MATCH(D19,RelNazivi,0))*IF(E19="ena smer",1,2),"")) | G19: =IF(F19="","",ROUND(F19*$J$3,2))
B20: =IF(WORKDAY(DATE(Leto,5,1)-1,11,Prazniki)>EOMONTH(DATE(Leto,5,1),0),"",WORKDAY(DATE(Leto,5,1)-1,11,Prazniki)) -> 46160 | F20: =IF(D20="","",IFERROR(INDEX(RelKm,MATCH(D20,RelNazivi,0))*IF(E20="ena smer",1,2),"")) | G20: =IF(F20="","",ROUND(F20*$J$3,2))
B21: =IF(WORKDAY(DATE(Leto,5,1)-1,12,Prazniki)>EOMONTH(DATE(Leto,5,1),0),"",WORKDAY(DATE(Leto,5,1)-1,12,Prazniki)) -> 46161 | F21: =IF(D21="","",IFERROR(INDEX(RelKm,MATCH(D21,RelNazivi,0))*IF(E21="ena smer",1,2),"")) | G21: =IF(F21="","",ROUND(F21*$J$3,2))
B22: =IF(WORKDAY(DATE(Leto,5,1)-1,13,Prazniki)>EOMONTH(DATE(Leto,5,1),0),"",WORKDAY(DATE(Leto,5,1)-1,13,Prazniki)) -> 46162 | F22: =IF(D22="","",IFERROR(INDEX(RelKm,MATCH(D22,RelNazivi,0))*IF(E22="ena smer",1,2),"")) | G22: =IF(F22="","",ROUND(F22*$J$3,2))
B23: =IF(WORKDAY(DATE(Leto,5,1)-1,14,Prazniki)>EOMONTH(DATE(Leto,5,1),0),"",WORKDAY(DATE(Leto,5,1)-1,14,Prazniki)) -> 46163 | F23: =IF(D23="","",IFERROR(INDEX(RelKm,MATCH(D23,RelNazivi,0))*IF(E23="ena smer",1,2),"")) | G23: =IF(F23="","",ROUND(F23*$J$3,2))
B24: =IF(WORKDAY(DATE(Leto,5,1)-1,15,Prazniki)>EOMONTH(DATE(Leto,5,1),0),"",WORKDAY(DATE(Leto,5,1)-1,15,Prazniki)) -> 46164 | F24: =IF(D24="","",IFERROR(INDEX(RelKm,MATCH(D24,RelNazivi,0))*IF(E24="ena smer",1,2),"")) | G24: =IF(F24="","",ROUND(F24*$J$3,2))
B25: =IF(WORKDAY(DATE(Leto,5,1)-1,16,Prazniki)>EOMONTH(DATE(Leto,5,1),0),"",WORKDAY(DATE(Leto,5,1)-1,16,Prazniki)) -> 46167 | F25: =IF(D25="","",IFERROR(INDEX(RelKm,MATCH(D25,RelNazivi,0))*IF(E25="ena smer",1,2),"")) | G25: =IF(F25="","",ROUND(F25*$J$3,2))
B26: =IF(WORKDAY(DATE(Leto,5,1)-1,17,Prazniki)>EOMONTH(DATE(Leto,5,1),0),"",WORKDAY(DATE(Leto,5,1)-1,17,Prazniki)) -> 46168 | F26: =IF(D26="","",IFERROR(INDEX(RelKm,MATCH(D26,RelNazivi,0))*IF(E26="ena smer",1,2),"")) | G26: =IF(F26="","",ROUND(F26*$J$3,2))
B27: =IF(WORKDAY(DATE(Leto,5,1)-1,18,Prazniki)>EOMONTH(DATE(Leto,5,1),0),"",WORKDAY(DATE(Leto,5,1)-1,18,Prazniki)) -> 46169 | F27: =IF(D27="","",IFERROR(INDEX(RelKm,MATCH(D27,RelNazivi,0))*IF(E27="ena smer",1,2),"")) | G27: =IF(F27="","",ROUND(F27*$J$3,2))
B28: =IF(WORKDAY(DATE(Leto,5,1)-1,19,Prazniki)>EOMONTH(DATE(Leto,5,1),0),"",WORKDAY(DATE(Leto,5,1)-1,19,Prazniki)) -> 46170 | F28: =IF(D28="","",IFERROR(INDEX(RelKm,MATCH(D28,RelNazivi,0))*IF(E28="ena smer",1,2),"")) | G28: =IF(F28="","",ROUND(F28*$J$3,2))
B29: =IF(WORKDAY(DATE(Leto,5,1)-1,20,Prazniki)>EOMONTH(DATE(Leto,5,1),0),"",WORKDAY(DATE(Leto,5,1)-1,20,Prazniki)) -> 46171 | F29: =IF(D29="","",IFERROR(INDEX(RelKm,MATCH(D29,RelNazivi,0))*IF(E29="ena smer",1,2),"")) | G29: =IF(F29="","",ROUND(F29*$J$3,2))
B30: =IF(WORKDAY(DATE(Leto,5,1)-1,21,Prazniki)>EOMONTH(DATE(Leto,5,1),0),"",WORKDAY(DATE(Leto,5,1)-1,21,Prazniki)) | F30: =IF(D30="","",IFERROR(INDEX(RelKm,MATCH(D30,RelNazivi,0))*IF(E30="ena smer",1,2),"")) | G30: =IF(F30="","",ROUND(F30*$J$3,2))
B31: =IF(WORKDAY(DATE(Leto,5,1)-1,22,Prazniki)>EOMONTH(DATE(Leto,5,1),0),"",WORKDAY(DATE(Leto,5,1)-1,22,Prazniki)) | F31: =IF(D31="","",IFERROR(INDEX(RelKm,MATCH(D31,RelNazivi,0))*IF(E31="ena smer",1,2),"")) | G31: =IF(F31="","",ROUND(F31*$J$3,2))
B32: =IF(WORKDAY(DATE(Leto,5,1)-1,23,Prazniki)>EOMONTH(DATE(Leto,5,1),0),"",WORKDAY(DATE(Leto,5,1)-1,23,Prazniki)) | F32: =IF(D32="","",IFERROR(INDEX(RelKm,MATCH(D32,RelNazivi,0))*IF(E32="ena smer",1,2),"")) | G32: =IF(F32="","",ROUND(F32*$J$3,2))
B33: =IF(WORKDAY(DATE(Leto,5,1)-1,24,Prazniki)>EOMONTH(DATE(Leto,5,1),0),"",WORKDAY(DATE(Leto,5,1)-1,24,Prazniki)) | F33: =IF(D33="","",IFERROR(INDEX(RelKm,MATCH(D33,RelNazivi,0))*IF(E33="ena smer",1,2),"")) | G33: =IF(F33="","",ROUND(F33*$J$3,2))
B34: =IF(WORKDAY(DATE(Leto,5,1)-1,25,Prazniki)>EOMONTH(DATE(Leto,5,1),0),"",WORKDAY(DATE(Leto,5,1)-1,25,Prazniki)) | F34: =IF(D34="","",IFERROR(INDEX(RelKm,MATCH(D34,RelNazivi,0))*IF(E34="ena smer",1,2),"")) | G34: =IF(F34="","",ROUND(F34*$J$3,2))
B35: =IF(WORKDAY(DATE(Leto,5,1)-1,26,Prazniki)>EOMONTH(DATE(Leto,5,1),0),"",WORKDAY(DATE(Leto,5,1)-1,26,Prazniki)) | F35: =IF(D35="","",IFERROR(INDEX(RelKm,MATCH(D35,RelNazivi,0))*IF(E35="ena smer",1,2),"")) | G35: =IF(F35="","",ROUND(F35*$J$3,2))
B36: =IF(WORKDAY(DATE(Leto,5,1)-1,27,Prazniki)>EOMONTH(DATE(Leto,5,1),0),"",WORKDAY(DATE(Leto,5,1)-1,27,Prazniki)) | F36: =IF(D36="","",IFERROR(INDEX(RelKm,MATCH(D36,RelNazivi,0))*IF(E36="ena smer",1,2),"")) | G36: =IF(F36="","",ROUND(F36*$J$3,2))
B37: =IF(WORKDAY(DATE(Leto,5,1)-1,28,Prazniki)>EOMONTH(DATE(Leto,5,1),0),"",WORKDAY(DATE(Leto,5,1)-1,28,Prazniki)) | F37: =IF(D37="","",IFERROR(INDEX(RelKm,MATCH(D37,RelNazivi,0))*IF(E37="ena smer",1,2),"")) | G37: =IF(F37="","",ROUND(F37*$J$3,2))
B38: =IF(WORKDAY(DATE(Leto,5,1)-1,29,Prazniki)>EOMONTH(DATE(Leto,5,1),0),"",WORKDAY(DATE(Leto,5,1)-1,29,Prazniki)) | F38: =IF(D38="","",IFERROR(INDEX(RelKm,MATCH(D38,RelNazivi,0))*IF(E38="ena smer",1,2),"")) | G38: =IF(F38="","",ROUND(F38*$J$3,2))
B39: =IF(WORKDAY(DATE(Leto,5,1)-1,30,Prazniki)>EOMONTH(DATE(Leto,5,1),0),"",WORKDAY(DATE(Leto,5,1)-1,30,Prazniki)) | F39: =IF(D39="","",IFERROR(INDEX(RelKm,MATCH(D39,RelNazivi,0))*IF(E39="ena smer",1,2),"")) | G39: =IF(F39="","",ROUND(F39*$J$3,2))
B40: =IF(WORKDAY(DATE(Leto,5,1)-1,31,Prazniki)>EOMONTH(DATE(Leto,5,1),0),"",WORKDAY(DATE(Leto,5,1)-1,31,Prazniki)) | F40: =IF(D40="","",IFERROR(INDEX(RelKm,MATCH(D40,RelNazivi,0))*IF(E40="ena smer",1,2),"")) | G40: =IF(F40="","",ROUND(F40*$J$3,2))
B41: SKUPAJ | F41: =SUM(F10:F40) -> 0 | G41: =SUM(G10:G40) -> 0
B42: *relacija se vpisuje od enote, kjer opravljate delo, do enote, kjer se odvija dogodek (izbira s seznama na listu Relacije)
...

Sheet Junij
B1: PODPISNI LIST - KILOMETRINA SLUŽBENIH POTI
I2: kilometrina
B3: =Ime -> Ime Priimek | I3: € / km | J3: =INDEX(KmCene,MATCH(DATE(Leto,6,1),KmDatumi,1)) -> 0.43
B4: =DelovnoMesto -> Enota | I4: delovni dnevi | J4: =NETWORKDAYS(DATE(Leto,6,1),EOMONTH(DATE(Leto,6,1),0),Prazniki) -> 21
B5: =DATE(Leto,6,1) -> 46174
B6: =Enote -> PALČEK, KRIŽE, DETELJICA, LOM, KOVOR
B9: DATUM | C9: DOGODEK / NAMEN POTI | D9: RELACIJA* | E9: POT | F9: KILOMETRI | G9: VREDNOST**
B10: =IF(WORKDAY(DATE(Leto,6,1)-1,1,Prazniki)>EOMONTH(DATE(Leto,6,1),0),"",WORKDAY(DATE(Leto,6,1)-1,1,Prazniki)) -> 46174 | F10: =IF(D10="","",IFERROR(INDEX(RelKm,MATCH(D10,RelNazivi,0))*IF(E10="ena smer",1,2),"")) | G10: =IF(F10="","",ROUND(F10*$J$3,2))
B11: =IF(WORKDAY(DATE(Leto,6,1)-1,2,Prazniki)>EOMONTH(DATE(Leto,6,1),0),"",WORKDAY(DATE(Leto,6,1)-1,2,Prazniki)) -> 46175 | F11: =IF(D11="","",IFERROR(INDEX(RelKm,MATCH(D11,RelNazivi,0))*IF(E11="ena smer",1,2),"")) | G11: =IF(F11="","",ROUND(F11*$J$3,2))
B12: =IF(WORKDAY(DATE(Leto,6,1)-1,3,Prazniki)>EOMONTH(DATE(Leto,6,1),0),"",WORKDAY(DATE(Leto,6,1)-1,3,Prazniki)) -> 46176 | F12: =IF(D12="","",IFERROR(INDEX(RelKm,MATCH(D12,RelNazivi,0))*IF(E12="ena smer",1,2),"")) | G12: =IF(F12="","",ROUND(F12*$J$3,2))
B13: =IF(WORKDAY(DATE(Leto,6,1)-1,4,Prazniki)>EOMONTH(DATE(Leto,6,1),0),"",WORKDAY(DATE(Leto,6,1)-1,4,Prazniki)) -> 46177 | F13: =IF(D13="","",IFERROR(INDEX(RelKm,MATCH(D13,RelNazivi,0))*IF(E13="ena smer",1,2),"")) | G13: =IF(F13="","",ROUND(F13*$J$3,2))
B14: =IF(WORKDAY(DATE(Leto,6,1)-1,5,Prazniki)>EOMONTH(DATE(Leto,6,1),0),"",WORKDAY(DATE(Leto,6,1)-1,5,Prazniki)) -> 46178 | F14: =IF(D14="","",IFERROR(INDEX(RelKm,MATCH(D14,RelNazivi,0))*IF(E14="ena smer",1,2),"")) | G14: =IF(F14="","",ROUND(F14*$J$3,2))
B15: =IF(WORKDAY(DATE(Leto,6,1)-1,6,Prazniki)>EOMONTH(DATE(Leto,6,1),0),"",WORKDAY(DATE(Leto,6,1)-1,6,Prazniki)) -> 46181 | F15: =IF(D15="","",IFERROR(INDEX(RelKm,MATCH(D15,RelNazivi,0))*IF(E15="ena smer",1,2),"")) | G15: =IF(F15="","",ROUND(F15*$J$3,2))
B16: =IF(WORKDAY(DATE(Leto,6,1)-1,7,Prazniki)>EOMONTH(DATE(Leto,6,1),0),"",WORKDAY(DATE(Leto,6,1)-1,7,Prazniki)) -> 46182 | F16: =IF(D16="","",IFERROR(INDEX(RelKm,MATCH(D16,RelNazivi,0))*IF(E16="ena smer",1,2),"")) | G16: =IF(F16="","",ROUND(F16*$J$3,2))
B17: =IF(WORKDAY(DATE(Leto,6,1)-1,8,Prazniki)>EOMONTH(DATE(Leto,6,1),0),"",WORKDAY(DATE(Leto,6,1)-1,8,Prazniki)) -> 46183 | F17: =IF(D17="","",IFERROR(INDEX(RelKm,MATCH(D17,RelNazivi,0))*IF(E17="ena smer",1,2),"")) | G17: =IF(F17="","",ROUND(F17*$J$3,2))
B18: =IF(WORKDAY(DATE(Leto,6,1)-1,9,Prazniki)>EOMONTH(DATE(Leto,6,1),0),"",WORKDAY(DATE(Leto,6,1)-1,9,Prazniki)) -> 46184 | F18: =IF(D18="","",IFERROR(INDEX(RelKm,MATCH(D18,RelNazivi,0))*IF(E18="ena smer",1,2),"")) | G18: =IF(F18="","",ROUND(F18*$J$3,2))
B19: =IF(WORKDAY(DATE(Leto,6,1)-1,10,Prazniki)>EOMONTH(DATE(Leto,6,1),0),"",WORKDAY(DATE(Leto,6,1)-1,10,Prazniki)) -> 46185 | F19: =IF(D19="","",IFERROR(INDEX(RelKm,MATCH(D19,RelNazivi,0))*IF(E19="ena smer",1,2),"")) | G19: =IF(F19="","",ROUND(F19*$J$3,2))
B20: =IF(WORKDAY(DATE(Leto,6,1)-1,11,Prazniki)>EOMONTH(DATE(Leto,6,1),0),"",WORKDAY(DATE(Leto,6,1)-1,11,Prazniki)) -> 46188 | F20: =IF(D20="","",IFERROR(INDEX(RelKm,MATCH(D20,RelNazivi,0))*IF(E20="ena smer",1,2),"")) | G20: =IF(F20="","",ROUND(F20*$J$3,2))
B21: =IF(WORKDAY(DATE(Leto,6,1)-1,12,Prazniki)>EOMONTH(DATE(Leto,6,1),0),"",WORKDAY(DATE(Leto,6,1)-1,12,Prazniki)) -> 46189 | F21: =IF(D21="","",IFERROR(INDEX(RelKm,MATCH(D21,RelNazivi,0))*IF(E21="ena smer",1,2),"")) | G21: =IF(F21="","",ROUND(F21*$J$3,2))
B22: =IF(WORKDAY(DATE(Leto,6,1)-1,13,Prazniki)>EOMONTH(DATE(Leto,6,1),0),"",WORKDAY(DATE(Leto,6,1)-1,13,Prazniki)) -> 46190 | F22: =IF(D22="","",IFERROR(INDEX(RelKm,MATCH(D22,RelNazivi,0))*IF(E22="ena smer",1,2),"")) | G22: =IF(F22="","",ROUND(F22*$J$3,2))
B23: =IF(WORKDAY(DATE(Leto,6,1)-1,14,Prazniki)>EOMONTH(DATE(Leto,6,1),0),"",WORKDAY(DATE(Leto,6,1)-1,14,Prazniki)) -> 46191 | F23: =IF(D23="","",IFERROR(INDEX(RelKm,MATCH(D23,RelNazivi,0))*IF(E23="ena smer",1,2),"")) | G23: =IF(F23="","",ROUND(F23*$J$3,2))
B24: =IF(WORKDAY(DATE(Leto,6,1)-1,15,Prazniki)>EOMONTH(DATE(Leto,6,1),0),"",WORKDAY(DATE(Leto,6,1)-1,15,Prazniki)) -> 46192 | F24: =IF(D24="","",IFERROR(INDEX(RelKm,MATCH(D24,RelNazivi,0))*IF(E24="ena smer",1,2),"")) | G24: =IF(F24="","",ROUND(F24*$J$3,2))
B25: =IF(WORKDAY(DATE(Leto,6,1)-1,16,Prazniki)>EOMONTH(DATE(Leto,6,1),0),"",WORKDAY(DATE(Leto,6,1)-1,16,Prazniki)) -> 46195 | F25: =IF(D25="","",IFERROR(INDEX(RelKm,MATCH(D25,RelNazivi,0))*IF(E25="ena smer",1,2),"")) | G25: =IF(F25="","",ROUND(F25*$J$3,2))
B26: =IF(WORKDAY(DATE(Leto,6,1)-1,17,Prazniki)>EOMONTH(DATE(Leto,6,1),0),"",WORKDAY(DATE(Leto,6,1)-1,17,Prazniki)) -> 46196 | F26: =IF(D26="","",IFERROR(INDEX(RelKm,MATCH(D26,RelNazivi,0))*IF(E26="ena smer",1,2),"")) | G26: =IF(F26="","",ROUND(F26*$J$3,2))
B27: =IF(WORKDAY(DATE(Leto,6,1)-1,18,Prazniki)>EOMONTH(DATE(Leto,6,1),0),"",WORKDAY(DATE(Leto,6,1)-1,18,Prazniki)) -> 46197 | F27: =IF(D27="","",IFERROR(INDEX(RelKm,MATCH(D27,RelNazivi,0))*IF(E27="ena smer",1,2),"")) | G27: =IF(F27="","",ROUND(F27*$J$3,2))
B28: =IF(WORKDAY(DATE(Leto,6,1)-1,19,Prazniki)>EOMONTH(DATE(Leto,6,1),0),"",WORKDAY(DATE(Leto,6,1)-1,19,Prazniki)) -> 46199 | F28: =IF(D28="","",IFERROR(INDEX(RelKm,MATCH(D28,RelNazivi,0))*IF(E28="ena smer",1,2),"")) | G28: =IF(F28="","",ROUND(F28*$J$3,2))
B29: =IF(WORKDAY(DATE(Leto,6,1)-1,20,Prazniki)>EOMONTH(DATE(Leto,6,1),0),"",WORKDAY(DATE(Leto,6,1)-1,20,Prazniki)) -> 46202 | F29: =IF(D29="","",IFERROR(INDEX(RelKm,MATCH(D29,RelNazivi,0))*IF(E29="ena smer",1,2),"")) | G29: =IF(F29="","",ROUND(F29*$J$3,2))
B30: =IF(WORKDAY(DATE(Leto,6,1)-1,21,Prazniki)>EOMONTH(DATE(Leto,6,1),0),"",WORKDAY(DATE(Leto,6,1)-1,21,Prazniki)) -> 46203 | F30: =IF(D30="","",IFERROR(INDEX(RelKm,MATCH(D30,RelNazivi,0))*IF(E30="ena smer",1,2),"")) | G30: =IF(F30="","",ROUND(F30*$J$3,2))
B31: =IF(WORKDAY(DATE(Leto,6,1)-1,22,Prazniki)>EOMONTH(DATE(Leto,6,1),0),"",WORKDAY(DATE(Leto,6,1)-1,22,Prazniki)) | F31: =IF(D31="","",IFERROR(INDEX(RelKm,MATCH(D31,RelNazivi,0))*IF(E31="ena smer",1,2),"")) | G31: =IF(F31="","",ROUND(F31*$J$3,2))
B32: =IF(WORKDAY(DATE(Leto,6,1)-1,23,Prazniki)>EOMONTH(DATE(Leto,6,1),0),"",WORKDAY(DATE(Leto,6,1)-1,23,Prazniki)) | F32: =IF(D32="","",IFERROR(INDEX(RelKm,MATCH(D32,RelNazivi,0))*IF(E32="ena smer",1,2),"")) | G32: =IF(F32="","",ROUND(F32*$J$3,2))
B33: =IF(WORKDAY(DATE(Leto,6,1)-1,24,Prazniki)>EOMONTH(DATE(Leto,6,1),0),"",WORKDAY(DATE(Leto,6,1)-1,24,Prazniki)) | F33: =IF(D33="","",IFERROR(INDEX(RelKm,MATCH(D33,RelNazivi,0))*IF(E33="ena smer",1,2),"")) | G33: =IF(F33="","",ROUND(F33*$J$3,2))
B34: =IF(WORKDAY(DATE(Leto,6,1)-1,25,Prazniki)>EOMONTH(DATE(Leto,6,1),0),"",WORKDAY(DATE(Leto,6,1)-1,25,Prazniki)) | F34: =IF(D34="","",IFERROR(INDEX(RelKm,MATCH(D34,RelNazivi,0))*IF(E34="ena smer",1,2),"")) | G34: =IF(F34="","",ROUND(F34*$J$3,2))
B35: =IF(WORKDAY(DATE(Leto,6,1)-1,26,Prazniki)>EOMONTH(DATE(Leto,6,1),0),"",WORKDAY(DATE(Leto,6,1)-1,26,Prazniki)) | F35: =IF(D35="","",IFERROR(INDEX(RelKm,MATCH(D35,RelNazivi,0))*IF(E35="ena smer",1,2),"")) | G35: =IF(F35="","",ROUND(F35*$J$3,2))
B36: =IF(WORKDAY(DATE(Leto,6,1)-1,27,Prazniki)>EOMONTH(DATE(Leto,6,1),0),"",WORKDAY(DATE(Leto,6,1)-1,27,Prazniki)) | F36: =IF(D36="","",IFERROR(INDEX(RelKm,MATCH(D36,RelNazivi,0))*IF(E36="ena smer",1,2),"")) | G36: =IF(F36="","",ROUND(F36*$J$3,2))
B37: =IF(WORKDAY(DATE(Leto,6,1)-1,28,Prazniki)>EOMONTH(DATE(Leto,6,1),0),"",WORKDAY(DATE(Leto,6,1)-1,28,Prazniki)) | F37: =IF(D37="","",IFERROR(INDEX(RelKm,MATCH(D37,RelNazivi,0))*IF(E37="ena smer",1,2),"")) | G37: =IF(F37="","",ROUND(F37*$J$3,2))
B38: =IF(WORKDAY(DATE(Leto,6,1)-1,29,Prazniki)>EOMONTH(DATE(Leto,6,1),0),"",WORKDAY(DATE(Leto,6,1)-1,29,Prazniki)) | F38: =IF(D38="","",IFERROR(INDEX(RelKm,MATCH(D38,RelNazivi,0))*IF(E38="ena smer",1,2),"")) | G38: =IF(F38="","",ROUND(F38*$J$3,2))
B39: =IF(WORKDAY(DATE(Leto,6,1)-1,30,Prazniki)>EOMONTH(DATE(Leto,6,1),0),"",WORKDAY(DATE(Leto,6,1)-1,30,Prazniki)) | F39: =IF(D39="","",IFERROR(INDEX(RelKm,MATCH(D39,RelNazivi,0))*IF(E39="ena smer",1,2),"")) | G39: =IF(F39="","",ROUND(F39*$J$3,2))
B40: =IF(WORKDAY(DATE(Leto,6,1)-1,31,Prazniki)>EOMONTH(DATE(Leto,6,1),0),"",WORKDAY(DATE(Leto,6,1)-1,31,Prazniki)) | F40: =IF(D40="","",IFERROR(INDEX(RelKm,MATCH(D40,RelNazivi,0))*IF(E40="ena smer",1,2),"")) | G40: =IF(F40="","",ROUND(F40*$J$3,2))
B41: SKUPAJ | F41: =SUM(F10:F40) -> 0 | G41: =SUM(G10:G40) -> 0
B42: *relacija se vpisuje od enote, kjer opravljate delo, do enote, kjer se odvija dogodek (izbira s seznama na listu Relacije)
...

Sheet Julij
B1: PODPISNI LIST - KILOMETRINA SLUŽBENIH POTI
I2: kilometrina
B3: =Ime -> Ime Priimek | I3: € / km | J3: =INDEX(KmCene,MATCH(DATE(Leto,7,1),KmDatumi,1)) -> 0.43
B4: =DelovnoMesto -> Enota | I4: delovni dnevi | J4: =NETWORKDAYS(DATE(Leto,7,1),EOMONTH(DATE(Leto,7,1),0),Prazniki) -> 23
B5: =DATE(Leto,7,1) -> 46204
B6: =Enote -> PALČEK, KRIŽE, DETELJICA, LOM, KOVOR
B9: DATUM | C9: DOGODEK / NAMEN POTI | D9: RELACIJA* | E9: POT | F9: KILOMETRI | G9: VREDNOST**
B10: =IF(WORKDAY(DATE(Leto,7,1)-1,1,Prazniki)>EOMONTH(DATE(Leto,7,1),0),"",WORKDAY(DATE(Leto,7,1)-1,1,Prazniki)) -> 46204 | F10: =IF(D10="","",IFERROR(INDEX(RelKm,MATCH(D10,RelNazivi,0))*IF(E10="ena smer",1,2),"")) | G10: =IF(F10="","",ROUND(F10*$J$3,2))
B11: =IF(WORKDAY(DATE(Leto,7,1)-1,2,Prazniki)>EOMONTH(DATE(Leto,7,1),0),"",WORKDAY(DATE(Leto,7,1)-1,2,Prazniki)) -> 46205 | F11: =IF(D11="","",IFERROR(INDEX(RelKm,MATCH(D11,RelNazivi,0))*IF(E11="ena smer",1,2),"")) | G11: =IF(F11="","",ROUND(F11*$J$3,2))
B12: =IF(WORKDAY(DATE(Leto,7,1)-1,3,Prazniki)>EOMONTH(DATE(Leto,7,1),0),"",WORKDAY(DATE(Leto,7,1)-1,3,Prazniki)) -> 46206 | F12: =IF(D12="","",IFERROR(INDEX(RelKm,MATCH(D12,RelNazivi,0))*IF(E12="ena smer",1,2),"")) | G12: =IF(F12="","",ROUND(F12*$J$3,2))
B13: =IF(WORKDAY(DATE(Leto,7,1)-1,4,Prazniki)>EOMONTH(DATE(Leto,7,1),0),"",WORKDAY(DATE(Leto,7,1)-1,4,Prazniki)) -> 46209 | F13: =IF(D13="","",IFERROR(INDEX(RelKm,MATCH(D13,RelNazivi,0))*IF(E13="ena smer",1,2),"")) | G13: =IF(F13="","",ROUND(F13*$J$3,2))
B14: =IF(WORKDAY(DATE(Leto,7,1)-1,5,Prazniki)>EOMONTH(DATE(Leto,7,1),0),"",WORKDAY(DATE(Leto,7,1)-1,5,Prazniki)) -> 46210 | F14: =IF(D14="","",IFERROR(INDEX(RelKm,MATCH(D14,RelNazivi,0))*IF(E14="ena smer",1,2),"")) | G14: =IF(F14="","",ROUND(F14*$J$3,2))
B15: =IF(WORKDAY(DATE(Leto,7,1)-1,6,Prazniki)>EOMONTH(DATE(Leto,7,1),0),"",WORKDAY(DATE(Leto,7,1)-1,6,Prazniki)) -> 46211 | F15: =IF(D15="","",IFERROR(INDEX(RelKm,MATCH(D15,RelNazivi,0))*IF(E15="ena smer",1,2),"")) | G15: =IF(F15="","",ROUND(F15*$J$3,2))
B16: =IF(WORKDAY(DATE(Leto,7,1)-1,7,Prazniki)>EOMONTH(DATE(Leto,7,1),0),"",WORKDAY(DATE(Leto,7,1)-1,7,Prazniki)) -> 46212 | F16: =IF(D16="","",IFERROR(INDEX(RelKm,MATCH(D16,RelNazivi,0))*IF(E16="ena smer",1,2),"")) | G16: =IF(F16="","",ROUND(F16*$J$3,2))
B17: =IF(WORKDAY(DATE(Leto,7,1)-1,8,Prazniki)>EOMONTH(DATE(Leto,7,1),0),"",WORKDAY(DATE(Leto,7,1)-1,8,Prazniki)) -> 46213 | F17: =IF(D17="","",IFERROR(INDEX(RelKm,MATCH(D17,RelNazivi,0))*IF(E17="ena smer",1,2),"")) | G17: =IF(F17="","",ROUND(F17*$J$3,2))
B18: =IF(WORKDAY(DATE(Leto,7,1)-1,9,Prazniki)>EOMONTH(DATE(Leto,7,1),0),"",WORKDAY(DATE(Leto,7,1)-1,9,Prazniki)) -> 46216 | F18: =IF(D18="","",IFERROR(INDEX(RelKm,MATCH(D18,RelNazivi,0))*IF(E18="ena smer",1,2),"")) | G18: =IF(F18="","",ROUND(F18*$J$3,2))
B19: =IF(WORKDAY(DATE(Leto,7,1)-1,10,Prazniki)>EOMONTH(DATE(Leto,7,1),0),"",WORKDAY(DATE(Leto,7,1)-1,10,Prazniki)) -> 46217 | F19: =IF(D19="","",IFERROR(INDEX(RelKm,MATCH(D19,RelNazivi,0))*IF(E19="ena smer",1,2),"")) | G19: =IF(F19="","",ROUND(F19*$J$3,2))
